//Schematic to java Structure by jajo_11 | inspired by "MITHION'S .SCHEMATIC TO JAVA CONVERTINGTOOL"

package com.Symbols97.OPWeapons.world;

import java.util.Random;

import com.Symbols97.OPWeapons.OPWeapons;
import com.Symbols97.OPWeapons.TileEntity.TileEntityDemonFurnace;

import net.minecraft.block.Block;
import net.minecraft.block.material.Material;
import net.minecraft.init.Blocks;
import net.minecraft.item.ItemStack;
import net.minecraft.tileentity.TileEntityChest;
import net.minecraft.tileentity.TileEntityFurnace;
import net.minecraft.world.World;
import net.minecraft.world.gen.feature.WorldGenerator;

public class OasisStructureDZ extends WorldGenerator
{
	protected Block[] GetValidSpawnBlocks()
	{
		return new Block[]
		{
			OPWeapons.blockofdemongem,
		};
	}

	public boolean LocationIsValidSpawn(World world, int x, int y, int z)
	{
		int distanceToAir = 0;
		Block checkBlock = world.getBlock(x, y, z);

		while (checkBlock != Blocks.air)
		{
			distanceToAir++;
			checkBlock = world.getBlock(x, y + distanceToAir, z);
		}

		if (distanceToAir > 1)
		{
			return false;
		}

		y += distanceToAir - 1;

		Block block = world.getBlock(x, y, z);
		Block blockAbove = world.getBlock(x, y + 1, z);
		Block blockBelow = world.getBlock(x, y - 1, z);

		for (Block i : GetValidSpawnBlocks())
		{
			if (blockAbove != Blocks.air)
			{
				return false;
			}
			if (block == i)
			{
				return true;
			}
			else if (block == Blocks.snow_layer && blockBelow == i)
			{
				return true;
			}
			else if (block.getMaterial() == Material.plants && blockBelow == i)
			{
				return true;
			}
		}
		return false;
	}

	public boolean generate(World world, Random rand, int x, int y, int z)
	{
		int i = rand.nextInt(40);

		if(i == 0)
		{
			generate_southfacing(world, rand, x, y, z);
		    //South Facing
		}

		if(i == 1)
		{
			generate_eastfacing(world, rand, x, y, z);
		    // East Facing
		}

		if(i == 2)
		{
			generate_northfacing(world, rand, x, y, z);
		    // North Facing
		}

		if(i == 3)
		{
			generate_westFacing(world, rand, x, y, z);
		    // West Facing
		}

       return true;

	}
	
	public static int raidedChance = 5;
	
	public boolean generate_southfacing(World world, Random rand, int x, int y, int z)
	{
		if(!LocationIsValidSpawn(world, x, y, z) || !LocationIsValidSpawn(world, x + 11, y, z) || !LocationIsValidSpawn(world, x + 11, y, z + 9) || !LocationIsValidSpawn(world, x, y, z + 9))
		{
			return false;
		}

		world.setBlock(x + 0, y + 0, z + 0, Blocks.air, 0, 3);
		world.setBlock(x + 1, y + 0, z + 0, Blocks.air, 0, 3);
		world.setBlock(x + 2, y + 0, z + 0, Blocks.air, 0, 3);
		world.setBlock(x + 3, y + 0, z + 0, Blocks.air, 0, 3);
		world.setBlock(x + 4, y + 0, z + 0, Blocks.nether_brick_fence, 0, 3);
		world.setBlock(x + 5, y + 0, z + 0, Blocks.nether_brick_stairs, 2, 3);
		world.setBlock(x + 6, y + 0, z + 0, Blocks.nether_brick_stairs, 2, 3);
		world.setBlock(x + 7, y + 0, z + 0, Blocks.nether_brick_fence, 0, 3);
		world.setBlock(x + 8, y + 0, z + 0, Blocks.air, 0, 3);
		world.setBlock(x + 9, y + 0, z + 0, Blocks.air, 0, 3);
		world.setBlock(x + 10, y + 0, z + 0, Blocks.air, 0, 3);
		world.setBlock(x + 11, y + 0, z + 0, Blocks.air, 0, 3);
		world.setBlock(x + 0, y + 0, z + 1, Blocks.nether_brick_fence, 0, 3);
		world.setBlock(x + 1, y + 0, z + 1, OPWeapons.demonLight, 0, 3);
		world.setBlock(x + 2, y + 0, z + 1, Blocks.air, 0, 3);
		world.setBlock(x + 3, y + 0, z + 1, Blocks.air, 0, 3);
		world.setBlock(x + 4, y + 0, z + 1, OPWeapons.condensedbodg, 14, 3);
		world.setBlock(x + 5, y + 0, z + 1, OPWeapons.condensedbodg, 14, 3);
		world.setBlock(x + 6, y + 0, z + 1, OPWeapons.condensedbodg, 14, 3);
		world.setBlock(x + 7, y + 0, z + 1, OPWeapons.condensedbodg, 14, 3);
		world.setBlock(x + 8, y + 0, z + 1, Blocks.air, 0, 3);
		world.setBlock(x + 9, y + 0, z + 1, Blocks.air, 0, 3);
		world.setBlock(x + 10, y + 0, z + 1, OPWeapons.demonLight, 0, 3);
		world.setBlock(x + 11, y + 0, z + 1, Blocks.nether_brick_fence, 0, 3);
		world.setBlock(x + 0, y + 0, z + 2, Blocks.air, 0, 3);
		world.setBlock(x + 1, y + 0, z + 2, OPWeapons.condensedbodg, 14, 3);
		world.setBlock(x + 2, y + 0, z + 2, OPWeapons.condensedbodg, 14, 3);
		world.setBlock(x + 3, y + 0, z + 2, OPWeapons.condensedbodg, 14, 3);
		world.setBlock(x + 4, y + 0, z + 2, OPWeapons.condensedbodg, 14, 3);
		world.setBlock(x + 5, y + 0, z + 2, OPWeapons.condensedbodg, 14, 3);
		world.setBlock(x + 6, y + 0, z + 2, OPWeapons.condensedbodg, 14, 3);
		world.setBlock(x + 7, y + 0, z + 2, OPWeapons.condensedbodg, 14, 3);
		world.setBlock(x + 8, y + 0, z + 2, OPWeapons.condensedbodg, 14, 3);
		world.setBlock(x + 9, y + 0, z + 2, OPWeapons.condensedbodg, 14, 3);
		world.setBlock(x + 10, y + 0, z + 2, OPWeapons.condensedbodg, 14, 3);
		world.setBlock(x + 11, y + 0, z + 2, Blocks.air, 0, 3);
		world.setBlock(x + 0, y + 0, z + 3, Blocks.air, 0, 3);
		world.setBlock(x + 1, y + 0, z + 3, OPWeapons.condensedbodg, 14, 3);
		world.setBlock(x + 2, y + 0, z + 3, OPWeapons.condensedbodg, 14, 3);
		world.setBlock(x + 3, y + 0, z + 3, OPWeapons.condensedbodg, 14, 3);
		world.setBlock(x + 4, y + 0, z + 3, OPWeapons.condensedbodg, 14, 3);
		world.setBlock(x + 5, y + 0, z + 3, OPWeapons.condensedbodg, 14, 3);
		world.setBlock(x + 6, y + 0, z + 3, OPWeapons.condensedbodg, 14, 3);
		world.setBlock(x + 7, y + 0, z + 3, OPWeapons.condensedbodg, 14, 3);
		world.setBlock(x + 8, y + 0, z + 3, OPWeapons.condensedbodg, 14, 3);
		world.setBlock(x + 9, y + 0, z + 3, OPWeapons.condensedbodg, 14, 3);
		world.setBlock(x + 10, y + 0, z + 3, OPWeapons.condensedbodg, 14, 3);
		world.setBlock(x + 11, y + 0, z + 3, Blocks.air, 0, 3);
		world.setBlock(x + 0, y + 0, z + 4, Blocks.air, 0, 3);
		world.setBlock(x + 1, y + 0, z + 4, OPWeapons.condensedbodg, 14, 3);
		world.setBlock(x + 2, y + 0, z + 4, OPWeapons.condensedbodg, 14, 3);
		world.setBlock(x + 3, y + 0, z + 4, OPWeapons.condensedbodg, 14, 3);
		world.setBlock(x + 4, y + 0, z + 4, OPWeapons.condensedbodg, 14, 3);
		world.setBlock(x + 5, y + 0, z + 4, OPWeapons.demonLight, 0, 3);
		world.setBlock(x + 6, y + 0, z + 4, OPWeapons.demonLight, 0, 3);
		world.setBlock(x + 7, y + 0, z + 4, OPWeapons.condensedbodg, 14, 3);
		world.setBlock(x + 8, y + 0, z + 4, OPWeapons.condensedbodg, 14, 3);
		world.setBlock(x + 9, y + 0, z + 4, OPWeapons.condensedbodg, 14, 3);
		world.setBlock(x + 10, y + 0, z + 4, OPWeapons.condensedbodg, 14, 3);
		world.setBlock(x + 11, y + 0, z + 4, Blocks.air, 0, 3);
		world.setBlock(x + 0, y + 0, z + 5, Blocks.air, 0, 3);
		world.setBlock(x + 1, y + 0, z + 5, OPWeapons.condensedbodg, 14, 3);
		world.setBlock(x + 2, y + 0, z + 5, OPWeapons.condensedbodg, 14, 3);
		world.setBlock(x + 3, y + 0, z + 5, OPWeapons.condensedbodg, 14, 3);
		world.setBlock(x + 4, y + 0, z + 5, OPWeapons.condensedbodg, 14, 3);
		world.setBlock(x + 5, y + 0, z + 5, OPWeapons.demonLight, 0, 3);
		world.setBlock(x + 6, y + 0, z + 5, OPWeapons.demonLight, 0, 3);
		world.setBlock(x + 7, y + 0, z + 5, OPWeapons.condensedbodg, 14, 3);
		world.setBlock(x + 8, y + 0, z + 5, OPWeapons.condensedbodg, 14, 3);
		world.setBlock(x + 9, y + 0, z + 5, OPWeapons.condensedbodg, 14, 3);
		world.setBlock(x + 10, y + 0, z + 5, OPWeapons.condensedbodg, 14, 3);
		world.setBlock(x + 11, y + 0, z + 5, Blocks.air, 0, 3);
		world.setBlock(x + 0, y + 0, z + 6, Blocks.air, 0, 3);
		world.setBlock(x + 1, y + 0, z + 6, OPWeapons.condensedbodg, 14, 3);
		world.setBlock(x + 2, y + 0, z + 6, OPWeapons.condensedbodg, 14, 3);
		world.setBlock(x + 3, y + 0, z + 6, OPWeapons.condensedbodg, 14, 3);
		world.setBlock(x + 4, y + 0, z + 6, OPWeapons.condensedbodg, 14, 3);
		world.setBlock(x + 5, y + 0, z + 6, OPWeapons.condensedbodg, 14, 3);
		world.setBlock(x + 6, y + 0, z + 6, OPWeapons.condensedbodg, 14, 3);
		world.setBlock(x + 7, y + 0, z + 6, OPWeapons.condensedbodg, 14, 3);
		world.setBlock(x + 8, y + 0, z + 6, OPWeapons.condensedbodg, 14, 3);
		world.setBlock(x + 9, y + 0, z + 6, OPWeapons.condensedbodg, 14, 3);
		world.setBlock(x + 10, y + 0, z + 6, OPWeapons.condensedbodg, 14, 3);
		world.setBlock(x + 11, y + 0, z + 6, Blocks.air, 0, 3);
		world.setBlock(x + 0, y + 0, z + 7, Blocks.air, 0, 3);
		world.setBlock(x + 1, y + 0, z + 7, OPWeapons.condensedbodg, 14, 3);
		world.setBlock(x + 2, y + 0, z + 7, OPWeapons.demonLight, 0, 3);
		world.setBlock(x + 3, y + 0, z + 7, OPWeapons.condensedbodg, 14, 3);
		world.setBlock(x + 4, y + 0, z + 7, OPWeapons.condensedbodg, 14, 3);
		world.setBlock(x + 5, y + 0, z + 7, OPWeapons.condensedbodg, 14, 3);
		world.setBlock(x + 6, y + 0, z + 7, OPWeapons.condensedbodg, 14, 3);
		world.setBlock(x + 7, y + 0, z + 7, OPWeapons.condensedbodg, 14, 3);
		world.setBlock(x + 8, y + 0, z + 7, OPWeapons.condensedbodg, 14, 3);
		world.setBlock(x + 9, y + 0, z + 7, OPWeapons.demonLight, 0, 3);
		world.setBlock(x + 10, y + 0, z + 7, OPWeapons.condensedbodg, 14, 3);
		world.setBlock(x + 11, y + 0, z + 7, Blocks.air, 0, 3);
		world.setBlock(x + 0, y + 0, z + 8, Blocks.air, 0, 3);
		world.setBlock(x + 1, y + 0, z + 8, OPWeapons.condensedbodg, 14, 3);
		world.setBlock(x + 2, y + 0, z + 8, OPWeapons.condensedbodg, 14, 3);
		world.setBlock(x + 3, y + 0, z + 8, OPWeapons.condensedbodg, 14, 3);
		world.setBlock(x + 4, y + 0, z + 8, OPWeapons.condensedbodg, 14, 3);
		world.setBlock(x + 5, y + 0, z + 8, OPWeapons.condensedbodg, 14, 3);
		world.setBlock(x + 6, y + 0, z + 8, OPWeapons.condensedbodg, 14, 3);
		world.setBlock(x + 7, y + 0, z + 8, OPWeapons.condensedbodg, 14, 3);
		world.setBlock(x + 8, y + 0, z + 8, OPWeapons.condensedbodg, 14, 3);
		world.setBlock(x + 9, y + 0, z + 8, OPWeapons.condensedbodg, 14, 3);
		world.setBlock(x + 10, y + 0, z + 8, OPWeapons.condensedbodg, 14, 3);
		world.setBlock(x + 11, y + 0, z + 8, Blocks.air, 0, 3);
		world.setBlock(x + 0, y + 0, z + 9, Blocks.nether_brick_fence, 0, 3);
		world.setBlock(x + 1, y + 0, z + 9, Blocks.air, 0, 3);
		world.setBlock(x + 2, y + 0, z + 9, Blocks.air, 0, 3);
		world.setBlock(x + 3, y + 0, z + 9, Blocks.air, 0, 3);
		world.setBlock(x + 4, y + 0, z + 9, Blocks.air, 0, 3);
		world.setBlock(x + 5, y + 0, z + 9, Blocks.air, 0, 3);
		world.setBlock(x + 6, y + 0, z + 9, Blocks.air, 0, 3);
		world.setBlock(x + 7, y + 0, z + 9, Blocks.air, 0, 3);
		world.setBlock(x + 8, y + 0, z + 9, Blocks.air, 0, 3);
		world.setBlock(x + 9, y + 0, z + 9, Blocks.air, 0, 3);
		world.setBlock(x + 10, y + 0, z + 9, Blocks.air, 0, 3);
		world.setBlock(x + 11, y + 0, z + 9, Blocks.nether_brick_fence, 0, 3);
		world.setBlock(x + 0, y + 1, z + 0, Blocks.air, 0, 3);
		world.setBlock(x + 1, y + 1, z + 0, Blocks.air, 0, 3);
		world.setBlock(x + 2, y + 1, z + 0, Blocks.air, 0, 3);
		world.setBlock(x + 3, y + 1, z + 0, Blocks.air, 0, 3);
		world.setBlock(x + 4, y + 1, z + 0, Blocks.nether_brick_fence, 0, 3);
		world.setBlock(x + 5, y + 1, z + 0, Blocks.air, 0, 3);
		world.setBlock(x + 6, y + 1, z + 0, Blocks.air, 0, 3);
		world.setBlock(x + 7, y + 1, z + 0, Blocks.nether_brick_fence, 0, 3);
		world.setBlock(x + 8, y + 1, z + 0, Blocks.air, 0, 3);
		world.setBlock(x + 9, y + 1, z + 0, Blocks.air, 0, 3);
		world.setBlock(x + 10, y + 1, z + 0, Blocks.air, 0, 3);
		world.setBlock(x + 11, y + 1, z + 0, Blocks.air, 0, 3);
		world.setBlock(x + 0, y + 1, z + 1, Blocks.nether_brick_fence, 0, 3);
		world.setBlock(x + 1, y + 1, z + 1, Blocks.air, 0, 3);
		world.setBlock(x + 2, y + 1, z + 1, Blocks.air, 0, 3);
		world.setBlock(x + 3, y + 1, z + 1, Blocks.air, 0, 3);
		world.setBlock(x + 4, y + 1, z + 1, OPWeapons.condensedbodg, 14, 3);
		world.setBlock(x + 5, y + 1, z + 1, Blocks.air, 0, 3);
		world.setBlock(x + 6, y + 1, z + 1, Blocks.air, 0, 3);
		world.setBlock(x + 7, y + 1, z + 1, OPWeapons.condensedbodg, 14, 3);
		world.setBlock(x + 8, y + 1, z + 1, Blocks.air, 0, 3);
		world.setBlock(x + 9, y + 1, z + 1, Blocks.air, 0, 3);
		world.setBlock(x + 10, y + 1, z + 1, Blocks.air, 0, 3);
		world.setBlock(x + 11, y + 1, z + 1, Blocks.nether_brick_fence, 0, 3);
		world.setBlock(x + 0, y + 1, z + 2, Blocks.air, 0, 3);
		world.setBlock(x + 1, y + 1, z + 2, OPWeapons.condensedbodg, 14, 3);
		world.setBlock(x + 2, y + 1, z + 2, OPWeapons.condensedbodg, 14, 3);
		world.setBlock(x + 3, y + 1, z + 2, OPWeapons.condensedbodg, 14, 3);
		world.setBlock(x + 4, y + 1, z + 2, Blocks.air, 0, 3);
		world.setBlock(x + 5, y + 1, z + 2, Blocks.air, 0, 3);
		world.setBlock(x + 6, y + 1, z + 2, Blocks.air, 0, 3);
		world.setBlock(x + 7, y + 1, z + 2, Blocks.air, 0, 3);
		world.setBlock(x + 8, y + 1, z + 2, OPWeapons.condensedbodg, 14, 3);
		world.setBlock(x + 9, y + 1, z + 2, OPWeapons.condensedbodg, 14, 3);
		world.setBlock(x + 10, y + 1, z + 2, OPWeapons.condensedbodg, 14, 3);
		world.setBlock(x + 11, y + 1, z + 2, Blocks.air, 0, 3);
		world.setBlock(x + 0, y + 1, z + 3, Blocks.air, 0, 3);
		world.setBlock(x + 1, y + 1, z + 3, OPWeapons.condensedbodg, 14, 3);
		world.setBlock(x + 2, y + 1, z + 3, OPWeapons.repairstation,1,1);
		world.setBlock(x + 3, y + 1, z + 3, Blocks.air, 0, 3);
		world.setBlock(x + 4, y + 1, z + 3, Blocks.air, 0, 3);
		world.setBlock(x + 5, y + 1, z + 3, Blocks.air, 0, 3);
		world.setBlock(x + 6, y + 1, z + 3, Blocks.air, 0, 3);
		world.setBlock(x + 7, y + 1, z + 3, Blocks.air, 0, 3);
		world.setBlock(x + 8, y + 1, z + 3, Blocks.air, 0, 3);
		world.setBlock(x + 9, y + 1, z + 3, Blocks.nether_brick_stairs, 3, 3);
		world.setBlock(x + 10, y + 1, z + 3, OPWeapons.condensedbodg, 14, 3);
		world.setBlock(x + 11, y + 1, z + 3, Blocks.air, 0, 3);
		world.setBlock(x + 0, y + 1, z + 4, Blocks.air, 0, 3);
		world.setBlock(x + 1, y + 1, z + 4, OPWeapons.condensedbodg, 14, 3);
		world.setBlock(x + 2, y + 1, z + 4, Blocks.air, 0, 3);
		world.setBlock(x + 3, y + 1, z + 4, Blocks.air, 0, 3);
		world.setBlock(x + 4, y + 1, z + 4, Blocks.air, 0, 3);
		world.setBlock(x + 5, y + 1, z + 4, Blocks.air, 0, 3);
		world.setBlock(x + 6, y + 1, z + 4, Blocks.air, 0, 3);
		world.setBlock(x + 7, y + 1, z + 4, Blocks.air, 0, 3);
		world.setBlock(x + 8, y + 1, z + 4, Blocks.air, 0, 3);
		world.setBlock(x + 9, y + 1, z + 4, Blocks.nether_brick_fence, 0, 3);
		world.setBlock(x + 10, y + 1, z + 4, OPWeapons.condensedbodg, 14, 3);
		world.setBlock(x + 11, y + 1, z + 4, Blocks.air, 0, 3);
		world.setBlock(x + 0, y + 1, z + 5, Blocks.air, 0, 3);
		world.setBlock(x + 1, y + 1, z + 5, OPWeapons.condensedbodg, 14, 3);
		world.setBlock(x + 2, y + 1, z + 5, Blocks.air, 0, 3);
		world.setBlock(x + 3, y + 1, z + 5, Blocks.air, 0, 3);
		world.setBlock(x + 4, y + 1, z + 5, Blocks.air, 0, 3);
		world.setBlock(x + 5, y + 1, z + 5, Blocks.air, 0, 3);
		world.setBlock(x + 6, y + 1, z + 5, Blocks.air, 0, 3);
		world.setBlock(x + 7, y + 1, z + 5, Blocks.air, 0, 3);
		world.setBlock(x + 8, y + 1, z + 5, Blocks.air, 0, 3);
		world.setBlock(x + 9, y + 1, z + 5, Blocks.nether_brick_stairs, 2, 3);
		world.setBlock(x + 10, y + 1, z + 5, OPWeapons.condensedbodg, 14, 3);
		world.setBlock(x + 11, y + 1, z + 5, Blocks.air, 0, 3);
		world.setBlock(x + 0, y + 1, z + 6, Blocks.air, 0, 3);
		world.setBlock(x + 1, y + 1, z + 6, OPWeapons.condensedbodg, 14, 3);
		world.setBlock(x + 2, y + 1, z + 6, Blocks.air, 0, 3);
		world.setBlock(x + 3, y + 1, z + 6, Blocks.air, 0, 3);
		world.setBlock(x + 4, y + 1, z + 6, Blocks.air, 0, 3);
		world.setBlock(x + 5, y + 1, z + 6, Blocks.air, 0, 3);
		world.setBlock(x + 6, y + 1, z + 6, Blocks.air, 0, 3);
		world.setBlock(x + 7, y + 1, z + 6, Blocks.air, 0, 3);
		world.setBlock(x + 8, y + 1, z + 6, Blocks.air, 0, 3);
		world.setBlock(x + 9, y + 1, z + 6, Blocks.air, 0, 3);
		world.setBlock(x + 10, y + 1, z + 6, OPWeapons.condensedbodg, 14, 3);
		world.setBlock(x + 11, y + 1, z + 6, Blocks.air, 0, 3);
		world.setBlock(x + 0, y + 1, z + 7, Blocks.air, 0, 3);
		world.setBlock(x + 1, y + 1, z + 7, OPWeapons.condensedbodg, 14, 3);
		world.setBlock(x + 2, y + 1, z + 7, Blocks.air, 0, 3);
		world.setBlock(x + 7, y + 1, z + 7, Blocks.crafting_table, 0, 3);
		world.setBlock(x + 9, y + 1, z + 7, Blocks.anvil, 3, 3);
		world.setBlock(x + 10, y + 1, z + 7, OPWeapons.condensedbodg, 14, 3);
		world.setBlock(x + 11, y + 1, z + 7, Blocks.air, 0, 3);
		world.setBlock(x + 0, y + 1, z + 8, Blocks.air, 0, 3);
		world.setBlock(x + 1, y + 1, z + 8, OPWeapons.condensedbodg, 14, 3);
		world.setBlock(x + 2, y + 1, z + 8, OPWeapons.condensedbodg, 14, 3);
		world.setBlock(x + 3, y + 1, z + 8, OPWeapons.condensedbodg, 14, 3);
		world.setBlock(x + 4, y + 1, z + 8, OPWeapons.condensedbodg, 14, 3);
		world.setBlock(x + 5, y + 1, z + 8, OPWeapons.condensedbodg, 14, 3);
		world.setBlock(x + 6, y + 1, z + 8, OPWeapons.condensedbodg, 14, 3);
		world.setBlock(x + 7, y + 1, z + 8, OPWeapons.condensedbodg, 14, 3);
		world.setBlock(x + 8, y + 1, z + 8, OPWeapons.condensedbodg, 14, 3);
		world.setBlock(x + 9, y + 1, z + 8, OPWeapons.condensedbodg, 14, 3);
		world.setBlock(x + 10, y + 1, z + 8, OPWeapons.condensedbodg, 14, 3);
		world.setBlock(x + 11, y + 1, z + 8, Blocks.air, 0, 3);
		world.setBlock(x + 0, y + 1, z + 9, Blocks.nether_brick_fence, 0, 3);
		world.setBlock(x + 1, y + 1, z + 9, Blocks.air, 0, 3);
		world.setBlock(x + 2, y + 1, z + 9, Blocks.air, 0, 3);
		world.setBlock(x + 3, y + 1, z + 9, Blocks.air, 0, 3);
		world.setBlock(x + 4, y + 1, z + 9, Blocks.air, 0, 3);
		world.setBlock(x + 5, y + 1, z + 9, Blocks.air, 0, 3);
		world.setBlock(x + 6, y + 1, z + 9, Blocks.air, 0, 3);
		world.setBlock(x + 7, y + 1, z + 9, Blocks.air, 0, 3);
		world.setBlock(x + 8, y + 1, z + 9, Blocks.air, 0, 3);
		world.setBlock(x + 9, y + 1, z + 9, Blocks.air, 0, 3);
		world.setBlock(x + 10, y + 1, z + 9, Blocks.air, 0, 3);
		world.setBlock(x + 11, y + 1, z + 9, Blocks.nether_brick_fence, 0, 3);
		world.setBlock(x + 0, y + 2, z + 0, Blocks.air, 0, 3);
		world.setBlock(x + 1, y + 2, z + 0, Blocks.air, 0, 3);
		world.setBlock(x + 2, y + 2, z + 0, Blocks.air, 0, 3);
		world.setBlock(x + 3, y + 2, z + 0, Blocks.air, 0, 3);
		world.setBlock(x + 5, y + 2, z + 0, Blocks.air, 0, 3);
		world.setBlock(x + 6, y + 2, z + 0, Blocks.air, 0, 3);
		world.setBlock(x + 8, y + 2, z + 0, Blocks.air, 0, 3);
		world.setBlock(x + 9, y + 2, z + 0, Blocks.air, 0, 3);
		world.setBlock(x + 10, y + 2, z + 0, Blocks.air, 0, 3);
		world.setBlock(x + 11, y + 2, z + 0, Blocks.air, 0, 3);
		world.setBlock(x + 0, y + 2, z + 1, Blocks.nether_brick_fence, 0, 3);
		world.setBlock(x + 1, y + 2, z + 1, Blocks.air, 0, 3);
		world.setBlock(x + 2, y + 2, z + 1, Blocks.air, 0, 3);
		world.setBlock(x + 3, y + 2, z + 1, Blocks.air, 0, 3);
		world.setBlock(x + 4, y + 2, z + 1, OPWeapons.condensedbodg, 14, 3);
		world.setBlock(x + 5, y + 2, z + 1, Blocks.air, 0, 3);
		world.setBlock(x + 6, y + 2, z + 1, Blocks.air, 0, 3);
		world.setBlock(x + 7, y + 2, z + 1, OPWeapons.condensedbodg, 14, 3);
		world.setBlock(x + 8, y + 2, z + 1, Blocks.air, 0, 3);
		world.setBlock(x + 9, y + 2, z + 1, Blocks.air, 0, 3);
		world.setBlock(x + 10, y + 2, z + 1, Blocks.air, 0, 3);
		world.setBlock(x + 11, y + 2, z + 1, Blocks.nether_brick_fence, 0, 3);
		world.setBlock(x + 0, y + 2, z + 2, Blocks.air, 0, 3);
		world.setBlock(x + 1, y + 2, z + 2, OPWeapons.condensedbodg, 14, 3);
		world.setBlock(x + 2, y + 2, z + 2, Blocks.glass, 0, 3);
		world.setBlock(x + 3, y + 2, z + 2, Blocks.glass, 0, 3);
		world.setBlock(x + 4, y + 2, z + 2, Blocks.air, 0, 3);
		world.setBlock(x + 5, y + 2, z + 2, Blocks.air, 0, 3);
		world.setBlock(x + 6, y + 2, z + 2, Blocks.air, 0, 3);
		world.setBlock(x + 7, y + 2, z + 2, Blocks.air, 0, 3);
		world.setBlock(x + 8, y + 2, z + 2, Blocks.glass, 0, 3);
		world.setBlock(x + 9, y + 2, z + 2, Blocks.glass, 0, 3);
		world.setBlock(x + 10, y + 2, z + 2, OPWeapons.condensedbodg, 14, 3);
		world.setBlock(x + 11, y + 2, z + 2, Blocks.air, 0, 3);
		world.setBlock(x + 0, y + 2, z + 3, Blocks.air, 0, 3);
		world.setBlock(x + 1, y + 2, z + 3, Blocks.glass, 0, 3);
		world.setBlock(x + 2, y + 2, z + 3, Blocks.air, 0, 3);
		world.setBlock(x + 3, y + 2, z + 3, Blocks.air, 0, 3);
		world.setBlock(x + 4, y + 2, z + 3, Blocks.air, 0, 3);
		world.setBlock(x + 5, y + 2, z + 3, Blocks.air, 0, 3);
		world.setBlock(x + 6, y + 2, z + 3, Blocks.air, 0, 3);
		world.setBlock(x + 7, y + 2, z + 3, Blocks.air, 0, 3);
		world.setBlock(x + 8, y + 2, z + 3, Blocks.air, 0, 3);
		world.setBlock(x + 9, y + 2, z + 3, Blocks.air, 0, 3);
		
		world.setBlock(x + 11, y + 2, z + 3, Blocks.air, 0, 3);
		world.setBlock(x + 0, y + 2, z + 4, Blocks.air, 0, 3);
		world.setBlock(x + 1, y + 2, z + 4, Blocks.glass, 0, 3);
		world.setBlock(x + 2, y + 2, z + 4, Blocks.air, 0, 3);
		world.setBlock(x + 3, y + 2, z + 4, Blocks.air, 0, 3);
		world.setBlock(x + 4, y + 2, z + 4, Blocks.air, 0, 3);
		world.setBlock(x + 5, y + 2, z + 4, Blocks.air, 0, 3);
		world.setBlock(x + 6, y + 2, z + 4, Blocks.air, 0, 3);
		world.setBlock(x + 7, y + 2, z + 4, Blocks.air, 0, 3);
		world.setBlock(x + 8, y + 2, z + 4, Blocks.air, 0, 3);
		world.setBlock(x + 9, y + 2, z + 4, Blocks.carpet, 7, 3);
		world.setBlock(x + 10, y + 2, z + 4, Blocks.glass, 0, 3);
		world.setBlock(x + 11, y + 2, z + 4, Blocks.air, 0, 3);
		world.setBlock(x + 0, y + 2, z + 5, Blocks.air, 0, 3);
		world.setBlock(x + 1, y + 2, z + 5, Blocks.glass, 0, 3);
		world.setBlock(x + 2, y + 2, z + 5, Blocks.air, 0, 3);
		world.setBlock(x + 3, y + 2, z + 5, Blocks.air, 0, 3);
		world.setBlock(x + 4, y + 2, z + 5, Blocks.air, 0, 3);
		world.setBlock(x + 5, y + 2, z + 5, Blocks.air, 0, 3);
		world.setBlock(x + 6, y + 2, z + 5, Blocks.air, 0, 3);
		world.setBlock(x + 7, y + 2, z + 5, Blocks.air, 0, 3);
		world.setBlock(x + 8, y + 2, z + 5, Blocks.air, 0, 3);
		world.setBlock(x + 9, y + 2, z + 5, Blocks.air, 0, 3);
		world.setBlock(x + 10, y + 2, z + 5, Blocks.glass, 0, 3);
		world.setBlock(x + 11, y + 2, z + 5, Blocks.air, 0, 3);
		world.setBlock(x + 0, y + 2, z + 6, Blocks.air, 0, 3);
		world.setBlock(x + 1, y + 2, z + 6, Blocks.glass, 0, 3);
		world.setBlock(x + 2, y + 2, z + 6, Blocks.air, 0, 3);
		world.setBlock(x + 3, y + 2, z + 6, Blocks.air, 0, 3);
		world.setBlock(x + 4, y + 2, z + 6, Blocks.air, 0, 3);
		world.setBlock(x + 5, y + 2, z + 6, Blocks.air, 0, 3);
		world.setBlock(x + 6, y + 2, z + 6, Blocks.air, 0, 3);
		world.setBlock(x + 7, y + 2, z + 6, Blocks.air, 0, 3);
		world.setBlock(x + 8, y + 2, z + 6, Blocks.air, 0, 3);
		world.setBlock(x + 9, y + 2, z + 6, Blocks.air, 0, 3);
		world.setBlock(x + 10, y + 2, z + 6, Blocks.glass, 0, 3);
		world.setBlock(x + 11, y + 2, z + 6, Blocks.air, 0, 3);
		world.setBlock(x + 0, y + 2, z + 7, Blocks.air, 0, 3);
		world.setBlock(x + 1, y + 2, z + 7, Blocks.glass, 0, 3);
		world.setBlock(x + 2, y + 2, z + 7, Blocks.air, 0, 3);
		world.setBlock(x + 3, y + 2, z + 7, Blocks.air, 0, 3);
		world.setBlock(x + 4, y + 2, z + 7, Blocks.air, 0, 3);
		world.setBlock(x + 5, y + 2, z + 7, Blocks.air, 0, 3);
		world.setBlock(x + 6, y + 2, z + 7, Blocks.air, 0, 3);
		world.setBlock(x + 7, y + 2, z + 7, Blocks.flower_pot, 1, 3);
		world.setBlock(x + 8, y + 2, z + 7, Blocks.air, 0, 3);
		world.setBlock(x + 9, y + 2, z + 7, Blocks.air, 0, 3);
		
		world.setBlock(x + 11, y + 2, z + 7, Blocks.air, 0, 3);
		world.setBlock(x + 0, y + 2, z + 8, Blocks.air, 0, 3);
		world.setBlock(x + 1, y + 2, z + 8, OPWeapons.condensedbodg, 14, 3);
		world.setBlock(x + 2, y + 2, z + 8, OPWeapons.condensedbodg, 14, 3);
		world.setBlock(x + 3, y + 2, z + 8, OPWeapons.condensedbodg, 14, 3);
		world.setBlock(x + 4, y + 2, z + 8, OPWeapons.condensedbodg, 14, 3);
		world.setBlock(x + 5, y + 2, z + 8, OPWeapons.condensedbodg, 14, 3);
		world.setBlock(x + 6, y + 2, z + 8, OPWeapons.condensedbodg, 14, 3);
		world.setBlock(x + 7, y + 2, z + 8, OPWeapons.condensedbodg, 14, 3);
		world.setBlock(x + 8, y + 2, z + 8, OPWeapons.condensedbodg, 14, 3);
		world.setBlock(x + 9, y + 2, z + 8, OPWeapons.condensedbodg, 14, 3);
		world.setBlock(x + 10, y + 2, z + 8, OPWeapons.condensedbodg, 14, 3);
		world.setBlock(x + 11, y + 2, z + 8, Blocks.air, 0, 3);
		world.setBlock(x + 0, y + 2, z + 9, Blocks.nether_brick_fence, 0, 3);
		world.setBlock(x + 1, y + 2, z + 9, Blocks.air, 0, 3);
		world.setBlock(x + 2, y + 2, z + 9, Blocks.air, 0, 3);
		world.setBlock(x + 3, y + 2, z + 9, Blocks.air, 0, 3);
		world.setBlock(x + 4, y + 2, z + 9, Blocks.air, 0, 3);
		world.setBlock(x + 5, y + 2, z + 9, Blocks.air, 0, 3);
		world.setBlock(x + 6, y + 2, z + 9, Blocks.air, 0, 3);
		world.setBlock(x + 7, y + 2, z + 9, Blocks.air, 0, 3);
		world.setBlock(x + 8, y + 2, z + 9, Blocks.air, 0, 3);
		world.setBlock(x + 9, y + 2, z + 9, Blocks.air, 0, 3);
		world.setBlock(x + 10, y + 2, z + 9, Blocks.air, 0, 3);
		world.setBlock(x + 11, y + 2, z + 9, Blocks.nether_brick_fence, 0, 3);
		world.setBlock(x + 0, y + 3, z + 0, Blocks.air, 0, 3);
		world.setBlock(x + 1, y + 3, z + 0, Blocks.air, 0, 3);
		world.setBlock(x + 2, y + 3, z + 0, Blocks.air, 0, 3);
		world.setBlock(x + 3, y + 3, z + 0, Blocks.air, 0, 3);
		world.setBlock(x + 4, y + 3, z + 0, Blocks.air, 0, 3);
		world.setBlock(x + 5, y + 3, z + 0, Blocks.air, 0, 3);
		world.setBlock(x + 6, y + 3, z + 0, Blocks.air, 0, 3);
		world.setBlock(x + 7, y + 3, z + 0, Blocks.air, 0, 3);
		world.setBlock(x + 8, y + 3, z + 0, Blocks.air, 0, 3);
		world.setBlock(x + 9, y + 3, z + 0, Blocks.air, 0, 3);
		world.setBlock(x + 10, y + 3, z + 0, Blocks.air, 0, 3);
		world.setBlock(x + 11, y + 3, z + 0, Blocks.air, 0, 3);
		world.setBlock(x + 0, y + 3, z + 1, Blocks.nether_brick_fence, 0, 3);
		world.setBlock(x + 1, y + 3, z + 1, Blocks.air, 0, 3);
		world.setBlock(x + 2, y + 3, z + 1, Blocks.air, 0, 3);
		world.setBlock(x + 3, y + 3, z + 1, Blocks.air, 0, 3);
		world.setBlock(x + 4, y + 3, z + 1, OPWeapons.condensedbodg, 14, 3);
		world.setBlock(x + 5, y + 3, z + 1, OPWeapons.condensedbodg, 14, 3);
		world.setBlock(x + 6, y + 3, z + 1, OPWeapons.condensedbodg, 14, 3);
		world.setBlock(x + 7, y + 3, z + 1, OPWeapons.condensedbodg, 14, 3);
		world.setBlock(x + 8, y + 3, z + 1, Blocks.air, 0, 3);
		world.setBlock(x + 9, y + 3, z + 1, Blocks.air, 0, 3);
		world.setBlock(x + 10, y + 3, z + 1, Blocks.air, 0, 3);
		world.setBlock(x + 11, y + 3, z + 1, Blocks.nether_brick_fence, 0, 3);
		world.setBlock(x + 0, y + 3, z + 2, Blocks.air, 0, 3);
		world.setBlock(x + 1, y + 3, z + 2, OPWeapons.condensedbodg, 14, 3);
		world.setBlock(x + 2, y + 3, z + 2, OPWeapons.condensedbodg, 14, 3);
		world.setBlock(x + 3, y + 3, z + 2, OPWeapons.condensedbodg, 14, 3);
		world.setBlock(x + 4, y + 3, z + 2, Blocks.air, 0, 3);
		world.setBlock(x + 5, y + 3, z + 2, Blocks.air, 0, 3);
		world.setBlock(x + 6, y + 3, z + 2, Blocks.air, 0, 3);
		world.setBlock(x + 7, y + 3, z + 2, Blocks.air, 0, 3);
		world.setBlock(x + 8, y + 3, z + 2, OPWeapons.condensedbodg, 14, 3);
		world.setBlock(x + 9, y + 3, z + 2, OPWeapons.condensedbodg, 14, 3);
		world.setBlock(x + 10, y + 3, z + 2, OPWeapons.condensedbodg, 14, 3);
		world.setBlock(x + 11, y + 3, z + 2, Blocks.air, 0, 3);
		world.setBlock(x + 0, y + 3, z + 3, Blocks.air, 0, 3);
		world.setBlock(x + 1, y + 3, z + 3, OPWeapons.condensedbodg, 14, 3);
		world.setBlock(x + 2, y + 3, z + 3, Blocks.air, 0, 3);
		world.setBlock(x + 3, y + 3, z + 3, Blocks.air, 0, 3);
		world.setBlock(x + 4, y + 3, z + 3, Blocks.air, 0, 3);
		world.setBlock(x + 5, y + 3, z + 3, Blocks.air, 0, 3);
		world.setBlock(x + 6, y + 3, z + 3, Blocks.air, 0, 3);
		world.setBlock(x + 7, y + 3, z + 3, Blocks.air, 0, 3);
		world.setBlock(x + 8, y + 3, z + 3, Blocks.air, 0, 3);
		world.setBlock(x + 9, y + 3, z + 3, Blocks.air, 0, 3);
		world.setBlock(x + 10, y + 3, z + 3, OPWeapons.condensedbodg, 14, 3);
		world.setBlock(x + 11, y + 3, z + 3, Blocks.air, 0, 3);
		world.setBlock(x + 0, y + 3, z + 4, Blocks.air, 0, 3);
		world.setBlock(x + 1, y + 3, z + 4, OPWeapons.condensedbodg, 14, 3);
		world.setBlock(x + 2, y + 3, z + 4, Blocks.air, 0, 3);
		world.setBlock(x + 3, y + 3, z + 4, Blocks.air, 0, 3);
		world.setBlock(x + 4, y + 3, z + 4, Blocks.air, 0, 3);
		world.setBlock(x + 5, y + 3, z + 4, Blocks.air, 0, 3);
		world.setBlock(x + 6, y + 3, z + 4, Blocks.air, 0, 3);
		world.setBlock(x + 7, y + 3, z + 4, Blocks.air, 0, 3);
		world.setBlock(x + 8, y + 3, z + 4, Blocks.air, 0, 3);
		world.setBlock(x + 9, y + 3, z + 4, Blocks.air, 0, 3);
		world.setBlock(x + 10, y + 3, z + 4, OPWeapons.condensedbodg, 14, 3);
		world.setBlock(x + 11, y + 3, z + 4, Blocks.air, 0, 3);
		world.setBlock(x + 0, y + 3, z + 5, Blocks.air, 0, 3);
		world.setBlock(x + 1, y + 3, z + 5, OPWeapons.condensedbodg, 14, 3);
		world.setBlock(x + 2, y + 3, z + 5, Blocks.air, 0, 3);
		world.setBlock(x + 3, y + 3, z + 5, Blocks.air, 0, 3);
		world.setBlock(x + 4, y + 3, z + 5, Blocks.air, 0, 3);
		world.setBlock(x + 5, y + 3, z + 5, Blocks.air, 0, 3);
		world.setBlock(x + 6, y + 3, z + 5, Blocks.air, 0, 3);
		world.setBlock(x + 7, y + 3, z + 5, Blocks.air, 0, 3);
		world.setBlock(x + 8, y + 3, z + 5, Blocks.air, 0, 3);
		world.setBlock(x + 9, y + 3, z + 5, Blocks.air, 0, 3);
		world.setBlock(x + 10, y + 3, z + 5, OPWeapons.condensedbodg, 14, 3);
		world.setBlock(x + 11, y + 3, z + 5, Blocks.air, 0, 3);
		world.setBlock(x + 0, y + 3, z + 6, Blocks.air, 0, 3);
		world.setBlock(x + 1, y + 3, z + 6, OPWeapons.condensedbodg, 14, 3);
		world.setBlock(x + 2, y + 3, z + 6, Blocks.air, 0, 3);
		world.setBlock(x + 3, y + 3, z + 6, Blocks.air, 0, 3);
		world.setBlock(x + 4, y + 3, z + 6, Blocks.air, 0, 3);
		world.setBlock(x + 5, y + 3, z + 6, Blocks.air, 0, 3);
		world.setBlock(x + 6, y + 3, z + 6, Blocks.air, 0, 3);
		world.setBlock(x + 7, y + 3, z + 6, Blocks.air, 0, 3);
		world.setBlock(x + 8, y + 3, z + 6, Blocks.air, 0, 3);
		world.setBlock(x + 9, y + 3, z + 6, Blocks.air, 0, 3);
		world.setBlock(x + 10, y + 3, z + 6, OPWeapons.condensedbodg, 14, 3);
		world.setBlock(x + 11, y + 3, z + 6, Blocks.air, 0, 3);
		world.setBlock(x + 0, y + 3, z + 7, Blocks.air, 0, 3);
		world.setBlock(x + 1, y + 3, z + 7, OPWeapons.condensedbodg, 14, 3);
		world.setBlock(x + 2, y + 3, z + 7, Blocks.air, 0, 3);
		world.setBlock(x + 3, y + 3, z + 7, Blocks.air, 0, 3);
		world.setBlock(x + 4, y + 3, z + 7, Blocks.air, 0, 3);
		world.setBlock(x + 5, y + 3, z + 7, Blocks.air, 0, 3);
		world.setBlock(x + 6, y + 3, z + 7, Blocks.air, 0, 3);
		world.setBlock(x + 7, y + 3, z + 7, Blocks.air, 0, 3);
		world.setBlock(x + 8, y + 3, z + 7, Blocks.air, 0, 3);
		world.setBlock(x + 9, y + 3, z + 7, Blocks.air, 0, 3);
		world.setBlock(x + 10, y + 3, z + 7, OPWeapons.condensedbodg, 14, 3);
		world.setBlock(x + 11, y + 3, z + 7, Blocks.air, 0, 3);
		world.setBlock(x + 0, y + 3, z + 8, Blocks.air, 0, 3);
		world.setBlock(x + 1, y + 3, z + 8, OPWeapons.condensedbodg, 14, 3);
		world.setBlock(x + 2, y + 3, z + 8, OPWeapons.condensedbodg, 14, 3);
		world.setBlock(x + 3, y + 3, z + 8, OPWeapons.condensedbodg, 14, 3);
		world.setBlock(x + 4, y + 3, z + 8, OPWeapons.condensedbodg, 14, 3);
		world.setBlock(x + 5, y + 3, z + 8, OPWeapons.condensedbodg, 14, 3);
		world.setBlock(x + 6, y + 3, z + 8, OPWeapons.condensedbodg, 14, 3);
		world.setBlock(x + 7, y + 3, z + 8, OPWeapons.condensedbodg, 14, 3);
		world.setBlock(x + 8, y + 3, z + 8, OPWeapons.condensedbodg, 14, 3);
		world.setBlock(x + 9, y + 3, z + 8, OPWeapons.condensedbodg, 14, 3);
		world.setBlock(x + 10, y + 3, z + 8, OPWeapons.condensedbodg, 14, 3);
		world.setBlock(x + 11, y + 3, z + 8, Blocks.air, 0, 3);
		world.setBlock(x + 0, y + 3, z + 9, Blocks.nether_brick_fence, 0, 3);
		world.setBlock(x + 1, y + 3, z + 9, Blocks.air, 0, 3);
		world.setBlock(x + 2, y + 3, z + 9, Blocks.air, 0, 3);
		world.setBlock(x + 3, y + 3, z + 9, Blocks.air, 0, 3);
		world.setBlock(x + 4, y + 3, z + 9, Blocks.air, 0, 3);
		world.setBlock(x + 5, y + 3, z + 9, Blocks.air, 0, 3);
		world.setBlock(x + 6, y + 3, z + 9, Blocks.air, 0, 3);
		world.setBlock(x + 7, y + 3, z + 9, Blocks.air, 0, 3);
		world.setBlock(x + 8, y + 3, z + 9, Blocks.air, 0, 3);
		world.setBlock(x + 9, y + 3, z + 9, Blocks.air, 0, 3);
		world.setBlock(x + 10, y + 3, z + 9, Blocks.air, 0, 3);
		world.setBlock(x + 11, y + 3, z + 9, Blocks.nether_brick_fence, 0, 3);
		world.setBlock(x + 0, y + 4, z + 0, Blocks.air, 0, 3);
		world.setBlock(x + 1, y + 4, z + 0, Blocks.air, 0, 3);
		world.setBlock(x + 2, y + 4, z + 0, Blocks.air, 0, 3);
		world.setBlock(x + 3, y + 4, z + 0, Blocks.air, 0, 3);
		world.setBlock(x + 4, y + 4, z + 0, Blocks.air, 0, 3);
		world.setBlock(x + 5, y + 4, z + 0, Blocks.air, 0, 3);
		world.setBlock(x + 6, y + 4, z + 0, Blocks.air, 0, 3);
		world.setBlock(x + 7, y + 4, z + 0, Blocks.air, 0, 3);
		world.setBlock(x + 8, y + 4, z + 0, Blocks.air, 0, 3);
		world.setBlock(x + 9, y + 4, z + 0, Blocks.air, 0, 3);
		world.setBlock(x + 10, y + 4, z + 0, Blocks.air, 0, 3);
		world.setBlock(x + 11, y + 4, z + 0, Blocks.air, 0, 3);
		world.setBlock(x + 0, y + 4, z + 1, Blocks.nether_brick_stairs, 2, 3);
		world.setBlock(x + 1, y + 4, z + 1, Blocks.nether_brick_stairs, 2, 3);
		world.setBlock(x + 2, y + 4, z + 1, Blocks.nether_brick_stairs, 2, 3);
		world.setBlock(x + 3, y + 4, z + 1, Blocks.nether_brick_stairs, 2, 3);
		world.setBlock(x + 4, y + 4, z + 1, OPWeapons.demonLight, 0, 3);
		world.setBlock(x + 5, y + 4, z + 1, OPWeapons.condensedbodg, 14, 3);
		world.setBlock(x + 6, y + 4, z + 1, OPWeapons.condensedbodg, 14, 3);
		world.setBlock(x + 7, y + 4, z + 1, OPWeapons.demonLight, 0, 3);
		world.setBlock(x + 8, y + 4, z + 1, Blocks.nether_brick_stairs, 2, 3);
		world.setBlock(x + 9, y + 4, z + 1, Blocks.nether_brick_stairs, 2, 3);
		world.setBlock(x + 10, y + 4, z + 1, Blocks.nether_brick_stairs, 2, 3);
		world.setBlock(x + 11, y + 4, z + 1, Blocks.nether_brick_stairs, 1, 3);
		world.setBlock(x + 0, y + 4, z + 2, Blocks.nether_brick_stairs, 0, 3);
		world.setBlock(x + 1, y + 4, z + 2, OPWeapons.condensedbodg, 14, 3);
		world.setBlock(x + 2, y + 4, z + 2, OPWeapons.condensedbodg, 14, 3);
		world.setBlock(x + 3, y + 4, z + 2, OPWeapons.condensedbodg, 14, 3);
		world.setBlock(x + 4, y + 4, z + 2, OPWeapons.condensedbodg, 14, 3);
		world.setBlock(x + 5, y + 4, z + 2, OPWeapons.condensedbodg, 14, 3);
		world.setBlock(x + 6, y + 4, z + 2, OPWeapons.condensedbodg, 14, 3);
		world.setBlock(x + 7, y + 4, z + 2, OPWeapons.condensedbodg, 14, 3);
		world.setBlock(x + 8, y + 4, z + 2, OPWeapons.condensedbodg, 14, 3);
		world.setBlock(x + 9, y + 4, z + 2, OPWeapons.condensedbodg, 14, 3);
		world.setBlock(x + 10, y + 4, z + 2, OPWeapons.condensedbodg, 14, 3);
		world.setBlock(x + 11, y + 4, z + 2, Blocks.nether_brick_stairs, 1, 3);
		world.setBlock(x + 0, y + 4, z + 3, Blocks.nether_brick_stairs, 0, 3);
		world.setBlock(x + 1, y + 4, z + 3, OPWeapons.condensedbodg, 14, 3);
		world.setBlock(x + 2, y + 4, z + 3, OPWeapons.condensedbodg, 14, 3);
		world.setBlock(x + 3, y + 4, z + 3, OPWeapons.condensedbodg, 14, 3);
		world.setBlock(x + 4, y + 4, z + 3, OPWeapons.condensedbodg, 14, 3);
		world.setBlock(x + 5, y + 4, z + 3, OPWeapons.condensedbodg, 14, 3);
		world.setBlock(x + 6, y + 4, z + 3, OPWeapons.condensedbodg, 14, 3);
		world.setBlock(x + 7, y + 4, z + 3, OPWeapons.condensedbodg, 14, 3);
		world.setBlock(x + 8, y + 4, z + 3, OPWeapons.condensedbodg, 14, 3);
		world.setBlock(x + 9, y + 4, z + 3, OPWeapons.condensedbodg, 14, 3);
		world.setBlock(x + 10, y + 4, z + 3, OPWeapons.condensedbodg, 14, 3);
		world.setBlock(x + 11, y + 4, z + 3, Blocks.nether_brick_stairs, 1, 3);
		world.setBlock(x + 0, y + 4, z + 4, Blocks.nether_brick_stairs, 0, 3);
		world.setBlock(x + 1, y + 4, z + 4, OPWeapons.condensedbodg, 14, 3);
		world.setBlock(x + 2, y + 4, z + 4, OPWeapons.condensedbodg, 14, 3);
		world.setBlock(x + 3, y + 4, z + 4, OPWeapons.condensedbodg, 14, 3);
		world.setBlock(x + 4, y + 4, z + 4, OPWeapons.condensedbodg, 14, 3);
		world.setBlock(x + 5, y + 4, z + 4, OPWeapons.demonLight, 0, 3);
		world.setBlock(x + 6, y + 4, z + 4, OPWeapons.demonLight, 0, 3);
		world.setBlock(x + 7, y + 4, z + 4, OPWeapons.condensedbodg, 14, 3);
		world.setBlock(x + 8, y + 4, z + 4, OPWeapons.condensedbodg, 14, 3);
		world.setBlock(x + 9, y + 4, z + 4, OPWeapons.condensedbodg, 14, 3);
		world.setBlock(x + 10, y + 4, z + 4, OPWeapons.condensedbodg, 14, 3);
		world.setBlock(x + 11, y + 4, z + 4, Blocks.nether_brick_stairs, 1, 3);
		world.setBlock(x + 0, y + 4, z + 5, Blocks.nether_brick_stairs, 0, 3);
		world.setBlock(x + 1, y + 4, z + 5, OPWeapons.condensedbodg, 14, 3);
		world.setBlock(x + 2, y + 4, z + 5, OPWeapons.condensedbodg, 14, 3);
		world.setBlock(x + 3, y + 4, z + 5, OPWeapons.condensedbodg, 14, 3);
		world.setBlock(x + 4, y + 4, z + 5, OPWeapons.condensedbodg, 14, 3);
		world.setBlock(x + 5, y + 4, z + 5, OPWeapons.demonLight, 0, 3);
		world.setBlock(x + 6, y + 4, z + 5, OPWeapons.demonLight, 0, 3);
		world.setBlock(x + 7, y + 4, z + 5, OPWeapons.condensedbodg, 14, 3);
		world.setBlock(x + 8, y + 4, z + 5, OPWeapons.condensedbodg, 14, 3);
		world.setBlock(x + 9, y + 4, z + 5, OPWeapons.condensedbodg, 14, 3);
		world.setBlock(x + 10, y + 4, z + 5, OPWeapons.condensedbodg, 14, 3);
		world.setBlock(x + 11, y + 4, z + 5, Blocks.nether_brick_stairs, 1, 3);
		world.setBlock(x + 0, y + 4, z + 6, Blocks.nether_brick_stairs, 0, 3);
		world.setBlock(x + 1, y + 4, z + 6, OPWeapons.condensedbodg, 14, 3);
		world.setBlock(x + 2, y + 4, z + 6, OPWeapons.condensedbodg, 14, 3);
		world.setBlock(x + 3, y + 4, z + 6, OPWeapons.condensedbodg, 14, 3);
		world.setBlock(x + 4, y + 4, z + 6, OPWeapons.condensedbodg, 14, 3);
		world.setBlock(x + 5, y + 4, z + 6, OPWeapons.condensedbodg, 14, 3);
		world.setBlock(x + 6, y + 4, z + 6, OPWeapons.condensedbodg, 14, 3);
		world.setBlock(x + 7, y + 4, z + 6, OPWeapons.condensedbodg, 14, 3);
		world.setBlock(x + 8, y + 4, z + 6, OPWeapons.condensedbodg, 14, 3);
		world.setBlock(x + 9, y + 4, z + 6, OPWeapons.condensedbodg, 14, 3);
		world.setBlock(x + 10, y + 4, z + 6, OPWeapons.condensedbodg, 14, 3);
		world.setBlock(x + 11, y + 4, z + 6, Blocks.nether_brick_stairs, 1, 3);
		world.setBlock(x + 0, y + 4, z + 7, Blocks.nether_brick_stairs, 0, 3);
		world.setBlock(x + 1, y + 4, z + 7, OPWeapons.condensedbodg, 14, 3);
		world.setBlock(x + 2, y + 4, z + 7, OPWeapons.condensedbodg, 14, 3);
		world.setBlock(x + 3, y + 4, z + 7, OPWeapons.condensedbodg, 14, 3);
		world.setBlock(x + 4, y + 4, z + 7, OPWeapons.condensedbodg, 14, 3);
		world.setBlock(x + 5, y + 4, z + 7, OPWeapons.condensedbodg, 14, 3);
		world.setBlock(x + 6, y + 4, z + 7, OPWeapons.condensedbodg, 14, 3);
		world.setBlock(x + 7, y + 4, z + 7, OPWeapons.condensedbodg, 14, 3);
		world.setBlock(x + 8, y + 4, z + 7, OPWeapons.condensedbodg, 14, 3);
		world.setBlock(x + 9, y + 4, z + 7, OPWeapons.condensedbodg, 14, 3);
		world.setBlock(x + 10, y + 4, z + 7, OPWeapons.condensedbodg, 14, 3);
		world.setBlock(x + 11, y + 4, z + 7, Blocks.nether_brick_stairs, 1, 3);
		world.setBlock(x + 0, y + 4, z + 8, Blocks.nether_brick_stairs, 0, 3);
		world.setBlock(x + 1, y + 4, z + 8, OPWeapons.condensedbodg, 14, 3);
		world.setBlock(x + 2, y + 4, z + 8, OPWeapons.condensedbodg, 14, 3);
		world.setBlock(x + 3, y + 4, z + 8, OPWeapons.condensedbodg, 14, 3);
		world.setBlock(x + 4, y + 4, z + 8, OPWeapons.condensedbodg, 14, 3);
		world.setBlock(x + 5, y + 4, z + 8, OPWeapons.condensedbodg, 14, 3);
		world.setBlock(x + 6, y + 4, z + 8, OPWeapons.condensedbodg, 14, 3);
		world.setBlock(x + 7, y + 4, z + 8, OPWeapons.condensedbodg, 14, 3);
		world.setBlock(x + 8, y + 4, z + 8, OPWeapons.condensedbodg, 14, 3);
		world.setBlock(x + 9, y + 4, z + 8, OPWeapons.condensedbodg, 14, 3);
		world.setBlock(x + 10, y + 4, z + 8, OPWeapons.condensedbodg, 14, 3);
		world.setBlock(x + 11, y + 4, z + 8, Blocks.nether_brick_stairs, 1, 3);
		world.setBlock(x + 0, y + 4, z + 9, Blocks.nether_brick_stairs, 0, 3);
		world.setBlock(x + 1, y + 4, z + 9, Blocks.nether_brick_stairs, 3, 3);
		world.setBlock(x + 2, y + 4, z + 9, Blocks.nether_brick_stairs, 3, 3);
		world.setBlock(x + 3, y + 4, z + 9, Blocks.nether_brick_stairs, 3, 3);
		world.setBlock(x + 4, y + 4, z + 9, Blocks.nether_brick_stairs, 3, 3);
		world.setBlock(x + 5, y + 4, z + 9, Blocks.nether_brick_stairs, 3, 3);
		world.setBlock(x + 6, y + 4, z + 9, Blocks.nether_brick_stairs, 3, 3);
		world.setBlock(x + 7, y + 4, z + 9, Blocks.nether_brick_stairs, 3, 3);
		world.setBlock(x + 8, y + 4, z + 9, Blocks.nether_brick_stairs, 3, 3);
		world.setBlock(x + 9, y + 4, z + 9, Blocks.nether_brick_stairs, 3, 3);
		world.setBlock(x + 10, y + 4, z + 9, Blocks.nether_brick_stairs, 3, 3);
		world.setBlock(x + 11, y + 4, z + 9, Blocks.nether_brick_stairs, 3, 3);
		world.setBlock(x + 0, y + 5, z + 0, Blocks.air, 0, 3);
		world.setBlock(x + 1, y + 5, z + 0, Blocks.air, 0, 3);
		world.setBlock(x + 2, y + 5, z + 0, Blocks.air, 0, 3);
		world.setBlock(x + 3, y + 5, z + 0, Blocks.air, 0, 3);
		world.setBlock(x + 4, y + 5, z + 0, Blocks.air, 0, 3);
		world.setBlock(x + 5, y + 5, z + 0, Blocks.air, 0, 3);
		world.setBlock(x + 6, y + 5, z + 0, Blocks.air, 0, 3);
		world.setBlock(x + 7, y + 5, z + 0, Blocks.air, 0, 3);
		world.setBlock(x + 8, y + 5, z + 0, Blocks.air, 0, 3);
		world.setBlock(x + 9, y + 5, z + 0, Blocks.air, 0, 3);
		world.setBlock(x + 10, y + 5, z + 0, Blocks.air, 0, 3);
		world.setBlock(x + 11, y + 5, z + 0, Blocks.air, 0, 3);
		world.setBlock(x + 0, y + 5, z + 1, Blocks.air, 0, 3);
		world.setBlock(x + 1, y + 5, z + 1, Blocks.air, 0, 3);
		world.setBlock(x + 2, y + 5, z + 1, Blocks.air, 0, 3);
		world.setBlock(x + 3, y + 5, z + 1, Blocks.air, 0, 3);
		world.setBlock(x + 4, y + 5, z + 1, Blocks.air, 0, 3);
		world.setBlock(x + 5, y + 5, z + 1, Blocks.air, 0, 3);
		world.setBlock(x + 6, y + 5, z + 1, Blocks.air, 0, 3);
		world.setBlock(x + 7, y + 5, z + 1, Blocks.air, 0, 3);
		world.setBlock(x + 8, y + 5, z + 1, Blocks.air, 0, 3);
		world.setBlock(x + 9, y + 5, z + 1, Blocks.air, 0, 3);
		world.setBlock(x + 10, y + 5, z + 1, Blocks.air, 0, 3);
		world.setBlock(x + 11, y + 5, z + 1, Blocks.air, 0, 3);
		world.setBlock(x + 0, y + 5, z + 2, Blocks.air, 0, 3);
		world.setBlock(x + 1, y + 5, z + 2, Blocks.nether_brick_stairs, 0, 3);
		world.setBlock(x + 2, y + 5, z + 2, Blocks.nether_brick_stairs, 2, 3);
		world.setBlock(x + 3, y + 5, z + 2, Blocks.nether_brick_stairs, 2, 3);
		world.setBlock(x + 4, y + 5, z + 2, Blocks.nether_brick_stairs, 2, 3);
		world.setBlock(x + 5, y + 5, z + 2, Blocks.nether_brick_stairs, 2, 3);
		world.setBlock(x + 6, y + 5, z + 2, Blocks.nether_brick_stairs, 2, 3);
		world.setBlock(x + 7, y + 5, z + 2, Blocks.nether_brick_stairs, 2, 3);
		world.setBlock(x + 8, y + 5, z + 2, Blocks.nether_brick_stairs, 2, 3);
		world.setBlock(x + 9, y + 5, z + 2, Blocks.nether_brick_stairs, 2, 3);
		world.setBlock(x + 10, y + 5, z + 2, Blocks.nether_brick_stairs, 2, 3);
		world.setBlock(x + 11, y + 5, z + 2, Blocks.air, 0, 3);
		world.setBlock(x + 0, y + 5, z + 3, Blocks.air, 0, 3);
		world.setBlock(x + 1, y + 5, z + 3, Blocks.nether_brick_stairs, 0, 3);
		world.setBlock(x + 2, y + 5, z + 3, Blocks.nether_brick, 0, 3);
		world.setBlock(x + 3, y + 5, z + 3, Blocks.nether_brick, 0, 3);
		world.setBlock(x + 4, y + 5, z + 3, Blocks.nether_brick, 0, 3);
		world.setBlock(x + 5, y + 5, z + 3, Blocks.nether_brick, 0, 3);
		world.setBlock(x + 6, y + 5, z + 3, Blocks.nether_brick, 0, 3);
		world.setBlock(x + 7, y + 5, z + 3, Blocks.nether_brick, 0, 3);
		world.setBlock(x + 8, y + 5, z + 3, Blocks.nether_brick, 0, 3);
		world.setBlock(x + 9, y + 5, z + 3, Blocks.nether_brick, 0, 3);
		world.setBlock(x + 10, y + 5, z + 3, Blocks.nether_brick_stairs, 1, 3);
		world.setBlock(x + 11, y + 5, z + 3, Blocks.air, 0, 3);
		world.setBlock(x + 0, y + 5, z + 4, Blocks.air, 0, 3);
		world.setBlock(x + 1, y + 5, z + 4, Blocks.nether_brick_stairs, 0, 3);
		world.setBlock(x + 2, y + 5, z + 4, Blocks.nether_brick, 0, 3);
		world.setBlock(x + 3, y + 5, z + 4, Blocks.nether_brick, 0, 3);
		world.setBlock(x + 4, y + 5, z + 4, Blocks.nether_brick, 0, 3);
		world.setBlock(x + 5, y + 5, z + 4, Blocks.nether_brick, 0, 3);
		world.setBlock(x + 6, y + 5, z + 4, Blocks.nether_brick, 0, 3);
		world.setBlock(x + 7, y + 5, z + 4, Blocks.nether_brick, 0, 3);
		world.setBlock(x + 8, y + 5, z + 4, Blocks.nether_brick, 0, 3);
		world.setBlock(x + 9, y + 5, z + 4, Blocks.nether_brick, 0, 3);
		world.setBlock(x + 10, y + 5, z + 4, Blocks.nether_brick_stairs, 1, 3);
		world.setBlock(x + 11, y + 5, z + 4, Blocks.air, 0, 3);
		world.setBlock(x + 0, y + 5, z + 5, Blocks.air, 0, 3);
		world.setBlock(x + 1, y + 5, z + 5, Blocks.nether_brick_stairs, 0, 3);
		world.setBlock(x + 2, y + 5, z + 5, Blocks.nether_brick, 0, 3);
		world.setBlock(x + 3, y + 5, z + 5, Blocks.nether_brick, 0, 3);
		world.setBlock(x + 4, y + 5, z + 5, Blocks.nether_brick, 0, 3);
		world.setBlock(x + 5, y + 5, z + 5, Blocks.nether_brick, 0, 3);
		world.setBlock(x + 6, y + 5, z + 5, Blocks.nether_brick, 0, 3);
		world.setBlock(x + 7, y + 5, z + 5, Blocks.nether_brick, 0, 3);
		world.setBlock(x + 8, y + 5, z + 5, Blocks.nether_brick, 0, 3);
		world.setBlock(x + 9, y + 5, z + 5, Blocks.nether_brick, 0, 3);
		world.setBlock(x + 10, y + 5, z + 5, Blocks.nether_brick_stairs, 1, 3);
		world.setBlock(x + 11, y + 5, z + 5, Blocks.air, 0, 3);
		world.setBlock(x + 0, y + 5, z + 6, Blocks.air, 0, 3);
		world.setBlock(x + 1, y + 5, z + 6, Blocks.nether_brick_stairs, 0, 3);
		world.setBlock(x + 2, y + 5, z + 6, Blocks.nether_brick, 0, 3);
		world.setBlock(x + 3, y + 5, z + 6, Blocks.nether_brick, 0, 3);
		world.setBlock(x + 4, y + 5, z + 6, Blocks.nether_brick, 0, 3);
		world.setBlock(x + 5, y + 5, z + 6, Blocks.nether_brick, 0, 3);
		world.setBlock(x + 6, y + 5, z + 6, Blocks.nether_brick, 0, 3);
		world.setBlock(x + 7, y + 5, z + 6, Blocks.nether_brick, 0, 3);
		world.setBlock(x + 8, y + 5, z + 6, Blocks.nether_brick, 0, 3);
		world.setBlock(x + 9, y + 5, z + 6, Blocks.nether_brick, 0, 3);
		world.setBlock(x + 10, y + 5, z + 6, Blocks.nether_brick_stairs, 1, 3);
		world.setBlock(x + 11, y + 5, z + 6, Blocks.air, 0, 3);
		world.setBlock(x + 0, y + 5, z + 7, Blocks.air, 0, 3);
		world.setBlock(x + 1, y + 5, z + 7, Blocks.nether_brick_stairs, 0, 3);
		world.setBlock(x + 2, y + 5, z + 7, Blocks.nether_brick, 0, 3);
		world.setBlock(x + 3, y + 5, z + 7, Blocks.nether_brick, 0, 3);
		world.setBlock(x + 4, y + 5, z + 7, Blocks.nether_brick, 0, 3);
		world.setBlock(x + 5, y + 5, z + 7, Blocks.nether_brick, 0, 3);
		world.setBlock(x + 6, y + 5, z + 7, Blocks.nether_brick, 0, 3);
		world.setBlock(x + 7, y + 5, z + 7, Blocks.nether_brick, 0, 3);
		world.setBlock(x + 8, y + 5, z + 7, Blocks.nether_brick, 0, 3);
		world.setBlock(x + 9, y + 5, z + 7, Blocks.nether_brick, 0, 3);
		world.setBlock(x + 10, y + 5, z + 7, Blocks.nether_brick_stairs, 1, 3);
		world.setBlock(x + 11, y + 5, z + 7, Blocks.air, 0, 3);
		world.setBlock(x + 0, y + 5, z + 8, Blocks.air, 0, 3);
		world.setBlock(x + 1, y + 5, z + 8, Blocks.nether_brick_stairs, 3, 3);
		world.setBlock(x + 2, y + 5, z + 8, Blocks.nether_brick_stairs, 3, 3);
		world.setBlock(x + 3, y + 5, z + 8, Blocks.nether_brick_stairs, 3, 3);
		world.setBlock(x + 4, y + 5, z + 8, Blocks.nether_brick_stairs, 3, 3);
		world.setBlock(x + 5, y + 5, z + 8, Blocks.nether_brick_stairs, 3, 3);
		world.setBlock(x + 6, y + 5, z + 8, Blocks.nether_brick_stairs, 3, 3);
		world.setBlock(x + 7, y + 5, z + 8, Blocks.nether_brick_stairs, 3, 3);
		world.setBlock(x + 8, y + 5, z + 8, Blocks.nether_brick_stairs, 3, 3);
		world.setBlock(x + 9, y + 5, z + 8, Blocks.nether_brick_stairs, 3, 3);
		world.setBlock(x + 10, y + 5, z + 8, Blocks.nether_brick_stairs, 1, 3);
		world.setBlock(x + 11, y + 5, z + 8, Blocks.air, 0, 3);
		world.setBlock(x + 0, y + 5, z + 9, Blocks.air, 0, 3);
		world.setBlock(x + 1, y + 5, z + 9, Blocks.air, 0, 3);
		world.setBlock(x + 2, y + 5, z + 9, Blocks.air, 0, 3);
		world.setBlock(x + 3, y + 5, z + 9, Blocks.air, 0, 3);
		world.setBlock(x + 4, y + 5, z + 9, Blocks.air, 0, 3);
		world.setBlock(x + 5, y + 5, z + 9, Blocks.air, 0, 3);
		world.setBlock(x + 6, y + 5, z + 9, Blocks.air, 0, 3);
		world.setBlock(x + 7, y + 5, z + 9, Blocks.air, 0, 3);
		world.setBlock(x + 8, y + 5, z + 9, Blocks.air, 0, 3);
		world.setBlock(x + 9, y + 5, z + 9, Blocks.air, 0, 3);
		world.setBlock(x + 10, y + 5, z + 9, Blocks.air, 0, 3);
		world.setBlock(x + 11, y + 5, z + 9, Blocks.air, 0, 3);
		world.setBlock(x + 4, y + 1, z + 7, OPWeapons.OPcraftingstation, 0, 3);

		int decorate = 1 + rand.nextInt(raidedChance);
		if (decorate == 4) {
			decorateSouthFacingRaided(world, rand, x, y, z);
		} else {
			decorateSouthFacing(world, rand, x, y, z);
		}
	
		
		
		return true;

	}
	
	public boolean decorateSouthFacing(World world, Random rand, int x, int y, int z)
	{
		
		world.setBlock(x + 5, y + 1, z + 7, Blocks.chest, 0, 2);
		world.setBlock(x + 6, y + 1, z + 7, Blocks.chest, 0, 2);
		world.setBlock(x + 8, y + 1, z + 7, Blocks.furnace,0,2);
		world.setBlock(x + 3, y + 1, z + 7, OPWeapons.DemonFurnaceIdle, 2, 3);
	
		TileEntityChest Loot = new TileEntityChest();
		TileEntityChest Loot1 = new TileEntityChest();
		
		
		world.setTileEntity(x + 5, y + 1, z + 7, Loot);
		world.setTileEntity(x + 6, y + 1, z + 7, Loot1);
	

		world.setBlock(x+5, y + 1, z+1, Blocks.wooden_door, 1 , 1);
		world.setBlock(x+5, y + 2, z+1, Blocks.wooden_door, 9, 1);
		world.setBlock(x+6, y + 1, z+1, Blocks.wooden_door, 1 , 1);
		world.setBlock(x+6, y + 2, z+1, Blocks.wooden_door, 8 , 1);
		
		world.setBlock(x + 2, y + 1, z + 6, Blocks.bed, 0 ,0);
		world.setBlock(x + 2, y + 1, z + 7, Blocks.bed, 8 ,0);
		
		world.setBlock(x + 10, y + 2, z + 3, Blocks.glass, 0, 3);
		world.setBlock(x + 10, y + 2, z + 7, Blocks.glass, 0, 3);
		world.setBlock(x + 4, y + 2, z + 0, Blocks.torch, 5, 3);
		world.setBlock(x + 7, y + 2, z + 0, Blocks.torch, 5, 3);
		
		lootTable(Loot, Loot1);
		
		
		
		return true;
	}
	
	public boolean decorateSouthFacingRaided(World world, Random rand, int x, int y, int z)
	{
		
		world.setBlock(x + 5, y + 1, z + 7, Blocks.chest, 0, 2);
		world.setBlock(x + 6, y + 1, z + 7, Blocks.chest, 0, 2);
		world.setBlock(x + 8, y + 1, z + 7, Blocks.furnace, 0, 2);
		world.setBlock(x + 3, y + 1, z + 7, OPWeapons.DemonFurnaceIdle, 2, 3);
		
		TileEntityChest Loot = new TileEntityChest();
		TileEntityChest Loot1 = new TileEntityChest();
		
		
		world.setTileEntity(x + 5, y + 1, z + 7, Loot);
		world.setTileEntity(x + 6, y + 1, z + 7, Loot1);
		

		
		world.setBlock(x+5, y + 1, z+1, Blocks.web, 0,0);
		world.setBlock(x + 2, y + 1, z + 7, Blocks.web, 0 ,0);
		world.setBlock(x + 9, y + 3, z + 7, Blocks.web, 0, 0);
		world.setBlock(x + 10, y + 2, z + 3, Blocks.web, 0, 3);
		world.setBlock(x + 10, y + 2, z + 7, Blocks.web, 0, 3);
		world.setBlock(x+6, y + 1, z+1, Blocks.wooden_door, 5 , 1);
		world.setBlock(x+6, y + 2, z+1, Blocks.wooden_door, 8 , 1);
		world.setBlock(x + 4, y + 2, z + 0, Blocks.torch, 5, 3);
		world.setBlock(x + 7, y + 2, z + 0, Blocks.vine, 1, 3);
		world.setBlock(x + 7, y + 3, z + 0, Blocks.vine, 1, 3);
		world.setBlock(x + 7, y + 4, z + 0, Blocks.vine, 1, 3);
		
		lootTableRaided(Loot, Loot1);
		
		return true;
	}

	public boolean generate_eastfacing(World world, Random rand, int x, int y, int z)
{
		if(!LocationIsValidSpawn(world, x, y, z) || !LocationIsValidSpawn(world, x + 9, y, z) || !LocationIsValidSpawn(world, x + 9, y, z + 11) || !LocationIsValidSpawn(world, x, y, z + 11))
		{
			return false;
		}

		world.setBlock(x + 0, y + 0, z + 11, Blocks.air, 0, 3);
		world.setBlock(x + 0, y + 0, z + 10, Blocks.air, 0, 3);
		world.setBlock(x + 0, y + 0, z + 9, Blocks.air, 0, 3);
		world.setBlock(x + 0, y + 0, z + 8, Blocks.air, 0, 3);
		world.setBlock(x + 0, y + 0, z + 7, Blocks.nether_brick_fence, 0, 3);
		world.setBlock(x + 0, y + 0, z + 6, Blocks.nether_brick_stairs, 0, 3);
		world.setBlock(x + 0, y + 0, z + 5, Blocks.nether_brick_stairs, 0, 3);
		world.setBlock(x + 0, y + 0, z + 4, Blocks.nether_brick_fence, 0, 3);
		world.setBlock(x + 0, y + 0, z + 3, Blocks.air, 0, 3);
		world.setBlock(x + 0, y + 0, z + 2, Blocks.air, 0, 3);
		world.setBlock(x + 0, y + 0, z + 1, Blocks.air, 0, 3);
		world.setBlock(x + 0, y + 0, z + 0, Blocks.air, 0, 3);
		world.setBlock(x + 1, y + 0, z + 11, Blocks.nether_brick_fence, 0, 3);
		world.setBlock(x + 1, y + 0, z + 10, OPWeapons.demonLight, 0, 3);
		world.setBlock(x + 1, y + 0, z + 9, Blocks.air, 0, 3);
		world.setBlock(x + 1, y + 0, z + 8, Blocks.air, 0, 3);
		world.setBlock(x + 1, y + 0, z + 7, OPWeapons.condensedbodg, 14, 3);
		world.setBlock(x + 1, y + 0, z + 6, OPWeapons.condensedbodg, 14, 3);
		world.setBlock(x + 1, y + 0, z + 5, OPWeapons.condensedbodg, 14, 3);
		world.setBlock(x + 1, y + 0, z + 4, OPWeapons.condensedbodg, 14, 3);
		world.setBlock(x + 1, y + 0, z + 3, Blocks.air, 0, 3);
		world.setBlock(x + 1, y + 0, z + 2, Blocks.air, 0, 3);
		world.setBlock(x + 1, y + 0, z + 1, OPWeapons.demonLight, 0, 3);
		world.setBlock(x + 1, y + 0, z + 0, Blocks.nether_brick_fence, 0, 3);
		world.setBlock(x + 2, y + 0, z + 11, Blocks.air, 0, 3);
		world.setBlock(x + 2, y + 0, z + 10, OPWeapons.condensedbodg, 14, 3);
		world.setBlock(x + 2, y + 0, z + 9, OPWeapons.condensedbodg, 14, 3);
		world.setBlock(x + 2, y + 0, z + 8, OPWeapons.condensedbodg, 14, 3);
		world.setBlock(x + 2, y + 0, z + 7, OPWeapons.condensedbodg, 14, 3);
		world.setBlock(x + 2, y + 0, z + 6, OPWeapons.condensedbodg, 14, 3);
		world.setBlock(x + 2, y + 0, z + 5, OPWeapons.condensedbodg, 14, 3);
		world.setBlock(x + 2, y + 0, z + 4, OPWeapons.condensedbodg, 14, 3);
		world.setBlock(x + 2, y + 0, z + 3, OPWeapons.condensedbodg, 14, 3);
		world.setBlock(x + 2, y + 0, z + 2, OPWeapons.condensedbodg, 14, 3);
		world.setBlock(x + 2, y + 0, z + 1, OPWeapons.condensedbodg, 14, 3);
		world.setBlock(x + 2, y + 0, z + 0, Blocks.air, 0, 3);
		world.setBlock(x + 3, y + 0, z + 11, Blocks.air, 0, 3);
		world.setBlock(x + 3, y + 0, z + 10, OPWeapons.condensedbodg, 14, 3);
		world.setBlock(x + 3, y + 0, z + 9, OPWeapons.condensedbodg, 14, 3);
		world.setBlock(x + 3, y + 0, z + 8, OPWeapons.condensedbodg, 14, 3);
		world.setBlock(x + 3, y + 0, z + 7, OPWeapons.condensedbodg, 14, 3);
		world.setBlock(x + 3, y + 0, z + 6, OPWeapons.condensedbodg, 14, 3);
		world.setBlock(x + 3, y + 0, z + 5, OPWeapons.condensedbodg, 14, 3);
		world.setBlock(x + 3, y + 0, z + 4, OPWeapons.condensedbodg, 14, 3);
		world.setBlock(x + 3, y + 0, z + 3, OPWeapons.condensedbodg, 14, 3);
		world.setBlock(x + 3, y + 0, z + 2, OPWeapons.condensedbodg, 14, 3);
		world.setBlock(x + 3, y + 0, z + 1, OPWeapons.condensedbodg, 14, 3);
		world.setBlock(x + 3, y + 0, z + 0, Blocks.air, 0, 3);
		world.setBlock(x + 4, y + 0, z + 11, Blocks.air, 0, 3);
		world.setBlock(x + 4, y + 0, z + 10, OPWeapons.condensedbodg, 14, 3);
		world.setBlock(x + 4, y + 0, z + 9, OPWeapons.condensedbodg, 14, 3);
		world.setBlock(x + 4, y + 0, z + 8, OPWeapons.condensedbodg, 14, 3);
		world.setBlock(x + 4, y + 0, z + 7, OPWeapons.condensedbodg, 14, 3);
		world.setBlock(x + 4, y + 0, z + 6, OPWeapons.demonLight, 0, 3);
		world.setBlock(x + 4, y + 0, z + 5, OPWeapons.demonLight, 0, 3);
		world.setBlock(x + 4, y + 0, z + 4, OPWeapons.condensedbodg, 14, 3);
		world.setBlock(x + 4, y + 0, z + 3, OPWeapons.condensedbodg, 14, 3);
		world.setBlock(x + 4, y + 0, z + 2, OPWeapons.condensedbodg, 14, 3);
		world.setBlock(x + 4, y + 0, z + 1, OPWeapons.condensedbodg, 14, 3);
		world.setBlock(x + 4, y + 0, z + 0, Blocks.air, 0, 3);
		world.setBlock(x + 5, y + 0, z + 11, Blocks.air, 0, 3);
		world.setBlock(x + 5, y + 0, z + 10, OPWeapons.condensedbodg, 14, 3);
		world.setBlock(x + 5, y + 0, z + 9, OPWeapons.condensedbodg, 14, 3);
		world.setBlock(x + 5, y + 0, z + 8, OPWeapons.condensedbodg, 14, 3);
		world.setBlock(x + 5, y + 0, z + 7, OPWeapons.condensedbodg, 14, 3);
		world.setBlock(x + 5, y + 0, z + 6, OPWeapons.demonLight, 0, 3);
		world.setBlock(x + 5, y + 0, z + 5, OPWeapons.demonLight, 0, 3);
		world.setBlock(x + 5, y + 0, z + 4, OPWeapons.condensedbodg, 14, 3);
		world.setBlock(x + 5, y + 0, z + 3, OPWeapons.condensedbodg, 14, 3);
		world.setBlock(x + 5, y + 0, z + 2, OPWeapons.condensedbodg, 14, 3);
		world.setBlock(x + 5, y + 0, z + 1, OPWeapons.condensedbodg, 14, 3);
		world.setBlock(x + 5, y + 0, z + 0, Blocks.air, 0, 3);
		world.setBlock(x + 6, y + 0, z + 11, Blocks.air, 0, 3);
		world.setBlock(x + 6, y + 0, z + 10, OPWeapons.condensedbodg, 14, 3);
		world.setBlock(x + 6, y + 0, z + 9, OPWeapons.condensedbodg, 14, 3);
		world.setBlock(x + 6, y + 0, z + 8, OPWeapons.condensedbodg, 14, 3);
		world.setBlock(x + 6, y + 0, z + 7, OPWeapons.condensedbodg, 14, 3);
		world.setBlock(x + 6, y + 0, z + 6, OPWeapons.condensedbodg, 14, 3);
		world.setBlock(x + 6, y + 0, z + 5, OPWeapons.condensedbodg, 14, 3);
		world.setBlock(x + 6, y + 0, z + 4, OPWeapons.condensedbodg, 14, 3);
		world.setBlock(x + 6, y + 0, z + 3, OPWeapons.condensedbodg, 14, 3);
		world.setBlock(x + 6, y + 0, z + 2, OPWeapons.condensedbodg, 14, 3);
		world.setBlock(x + 6, y + 0, z + 1, OPWeapons.condensedbodg, 14, 3);
		world.setBlock(x + 6, y + 0, z + 0, Blocks.air, 0, 3);
		world.setBlock(x + 7, y + 0, z + 11, Blocks.air, 0, 3);
		world.setBlock(x + 7, y + 0, z + 10, OPWeapons.condensedbodg, 14, 3);
		world.setBlock(x + 7, y + 0, z + 9, OPWeapons.demonLight, 0, 3);
		world.setBlock(x + 7, y + 0, z + 8, OPWeapons.condensedbodg, 14, 3);
		world.setBlock(x + 7, y + 0, z + 7, OPWeapons.condensedbodg, 14, 3);
		world.setBlock(x + 7, y + 0, z + 6, OPWeapons.condensedbodg, 14, 3);
		world.setBlock(x + 7, y + 0, z + 5, OPWeapons.condensedbodg, 14, 3);
		world.setBlock(x + 7, y + 0, z + 4, OPWeapons.condensedbodg, 14, 3);
		world.setBlock(x + 7, y + 0, z + 3, OPWeapons.condensedbodg, 14, 3);
		world.setBlock(x + 7, y + 0, z + 2, OPWeapons.demonLight, 0, 3);
		world.setBlock(x + 7, y + 0, z + 1, OPWeapons.condensedbodg, 14, 3);
		world.setBlock(x + 7, y + 0, z + 0, Blocks.air, 0, 3);
		world.setBlock(x + 8, y + 0, z + 11, Blocks.air, 0, 3);
		world.setBlock(x + 8, y + 0, z + 10, OPWeapons.condensedbodg, 14, 3);
		world.setBlock(x + 8, y + 0, z + 9, OPWeapons.condensedbodg, 14, 3);
		world.setBlock(x + 8, y + 0, z + 8, OPWeapons.condensedbodg, 14, 3);
		world.setBlock(x + 8, y + 0, z + 7, OPWeapons.condensedbodg, 14, 3);
		world.setBlock(x + 8, y + 0, z + 6, OPWeapons.condensedbodg, 14, 3);
		world.setBlock(x + 8, y + 0, z + 5, OPWeapons.condensedbodg, 14, 3);
		world.setBlock(x + 8, y + 0, z + 4, OPWeapons.condensedbodg, 14, 3);
		world.setBlock(x + 8, y + 0, z + 3, OPWeapons.condensedbodg, 14, 3);
		world.setBlock(x + 8, y + 0, z + 2, OPWeapons.condensedbodg, 14, 3);
		world.setBlock(x + 8, y + 0, z + 1, OPWeapons.condensedbodg, 14, 3);
		world.setBlock(x + 8, y + 0, z + 0, Blocks.air, 0, 3);
		world.setBlock(x + 9, y + 0, z + 11, Blocks.nether_brick_fence, 0, 3);
		world.setBlock(x + 9, y + 0, z + 10, Blocks.air, 0, 3);
		world.setBlock(x + 9, y + 0, z + 9, Blocks.air, 0, 3);
		world.setBlock(x + 9, y + 0, z + 8, Blocks.air, 0, 3);
		world.setBlock(x + 9, y + 0, z + 7, Blocks.air, 0, 3);
		world.setBlock(x + 9, y + 0, z + 6, Blocks.air, 0, 3);
		world.setBlock(x + 9, y + 0, z + 5, Blocks.air, 0, 3);
		world.setBlock(x + 9, y + 0, z + 4, Blocks.air, 0, 3);
		world.setBlock(x + 9, y + 0, z + 3, Blocks.air, 0, 3);
		world.setBlock(x + 9, y + 0, z + 2, Blocks.air, 0, 3);
		world.setBlock(x + 9, y + 0, z + 1, Blocks.air, 0, 3);
		world.setBlock(x + 9, y + 0, z + 0, Blocks.nether_brick_fence, 0, 3);
		world.setBlock(x + 0, y + 1, z + 11, Blocks.air, 0, 3);
		world.setBlock(x + 0, y + 1, z + 10, Blocks.air, 0, 3);
		world.setBlock(x + 0, y + 1, z + 9, Blocks.air, 0, 3);
		world.setBlock(x + 0, y + 1, z + 8, Blocks.air, 0, 3);
		world.setBlock(x + 0, y + 1, z + 7, Blocks.nether_brick_fence, 0, 3);
		world.setBlock(x + 0, y + 1, z + 6, Blocks.air, 0, 3);
		world.setBlock(x + 0, y + 1, z + 5, Blocks.air, 0, 3);
		world.setBlock(x + 0, y + 1, z + 4, Blocks.nether_brick_fence, 0, 3);
		world.setBlock(x + 0, y + 1, z + 3, Blocks.air, 0, 3);
		world.setBlock(x + 0, y + 1, z + 2, Blocks.air, 0, 3);
		world.setBlock(x + 0, y + 1, z + 1, Blocks.air, 0, 3);
		world.setBlock(x + 0, y + 1, z + 0, Blocks.air, 0, 3);
		world.setBlock(x + 1, y + 1, z + 11, Blocks.nether_brick_fence, 0, 3);
		world.setBlock(x + 1, y + 1, z + 10, Blocks.air, 0, 3);
		world.setBlock(x + 1, y + 1, z + 9, Blocks.air, 0, 3);
		world.setBlock(x + 1, y + 1, z + 8, Blocks.air, 0, 3);
		world.setBlock(x + 1, y + 1, z + 7, OPWeapons.condensedbodg, 14, 3);
		world.setBlock(x + 1, y + 1, z + 6, Blocks.air, 0, 3);
		world.setBlock(x + 1, y + 1, z + 5, Blocks.air, 0, 3);
		world.setBlock(x + 1, y + 1, z + 4, OPWeapons.condensedbodg, 14, 3);
		world.setBlock(x + 1, y + 1, z + 3, Blocks.air, 0, 3);
		world.setBlock(x + 1, y + 1, z + 2, Blocks.air, 0, 3);
		world.setBlock(x + 1, y + 1, z + 1, Blocks.air, 0, 3);
		world.setBlock(x + 1, y + 1, z + 0, Blocks.nether_brick_fence, 0, 3);
		world.setBlock(x + 2, y + 1, z + 11, Blocks.air, 0, 3);
		world.setBlock(x + 2, y + 1, z + 10, OPWeapons.condensedbodg, 14, 3);
		world.setBlock(x + 2, y + 1, z + 9, OPWeapons.condensedbodg, 14, 3);
		world.setBlock(x + 2, y + 1, z + 8, OPWeapons.condensedbodg, 14, 3);
		world.setBlock(x + 2, y + 1, z + 7, Blocks.air, 0, 3);
		world.setBlock(x + 2, y + 1, z + 6, Blocks.air, 0, 3);
		world.setBlock(x + 2, y + 1, z + 5, Blocks.air, 0, 3);
		world.setBlock(x + 2, y + 1, z + 4, Blocks.air, 0, 3);
		world.setBlock(x + 2, y + 1, z + 3, OPWeapons.condensedbodg, 14, 3);
		world.setBlock(x + 2, y + 1, z + 2, OPWeapons.condensedbodg, 14, 3);
		world.setBlock(x + 2, y + 1, z + 1, OPWeapons.condensedbodg, 14, 3);
		world.setBlock(x + 2, y + 1, z + 0, Blocks.air, 0, 3);
		world.setBlock(x + 3, y + 1, z + 11, Blocks.air, 0, 3);
		world.setBlock(x + 3, y + 1, z + 10, OPWeapons.condensedbodg, 14, 3);
		world.setBlock(x + 3, y + 1, z + 9, OPWeapons.repairstation, 0, 3);
		world.setBlock(x + 3, y + 1, z + 8, Blocks.air, 0, 3);
		world.setBlock(x + 3, y + 1, z + 7, Blocks.air, 0, 3);
		world.setBlock(x + 3, y + 1, z + 6, Blocks.air, 0, 3);
		world.setBlock(x + 3, y + 1, z + 5, Blocks.air, 0, 3);
		world.setBlock(x + 3, y + 1, z + 4, Blocks.air, 0, 3);
		world.setBlock(x + 3, y + 1, z + 3, Blocks.air, 0, 3);
		world.setBlock(x + 3, y + 1, z + 2, Blocks.nether_brick_stairs, 1, 3);
		world.setBlock(x + 3, y + 1, z + 1, OPWeapons.condensedbodg, 14, 3);
		world.setBlock(x + 3, y + 1, z + 0, Blocks.air, 0, 3);
		world.setBlock(x + 4, y + 1, z + 11, Blocks.air, 0, 3);
		world.setBlock(x + 4, y + 1, z + 10, OPWeapons.condensedbodg, 14, 3);
		world.setBlock(x + 4, y + 1, z + 9, Blocks.air, 0, 3);
		world.setBlock(x + 4, y + 1, z + 8, Blocks.air, 0, 3);
		world.setBlock(x + 4, y + 1, z + 7, Blocks.air, 0, 3);
		world.setBlock(x + 4, y + 1, z + 6, Blocks.air, 0, 3);
		world.setBlock(x + 4, y + 1, z + 5, Blocks.air, 0, 3);
		world.setBlock(x + 4, y + 1, z + 4, Blocks.air, 0, 3);
		world.setBlock(x + 4, y + 1, z + 3, Blocks.air, 0, 3);
		world.setBlock(x + 4, y + 1, z + 2, Blocks.nether_brick_fence, 0, 3);
		world.setBlock(x + 4, y + 1, z + 1, OPWeapons.condensedbodg, 14, 3);
		world.setBlock(x + 4, y + 1, z + 0, Blocks.air, 0, 3);
		world.setBlock(x + 5, y + 1, z + 11, Blocks.air, 0, 3);
		world.setBlock(x + 5, y + 1, z + 10, OPWeapons.condensedbodg, 14, 3);
		world.setBlock(x + 5, y + 1, z + 9, Blocks.air, 0, 3);
		world.setBlock(x + 5, y + 1, z + 8, Blocks.air, 0, 3);
		world.setBlock(x + 5, y + 1, z + 7, Blocks.air, 0, 3);
		world.setBlock(x + 5, y + 1, z + 6, Blocks.air, 0, 3);
		world.setBlock(x + 5, y + 1, z + 5, Blocks.air, 0, 3);
		world.setBlock(x + 5, y + 1, z + 4, Blocks.air, 0, 3);
		world.setBlock(x + 5, y + 1, z + 3, Blocks.air, 0, 3);
		world.setBlock(x + 5, y + 1, z + 2, Blocks.nether_brick_stairs, 0, 3);
		world.setBlock(x + 5, y + 1, z + 1, OPWeapons.condensedbodg, 14, 3);
		world.setBlock(x + 5, y + 1, z + 0, Blocks.air, 0, 3);
		world.setBlock(x + 6, y + 1, z + 11, Blocks.air, 0, 3);
		world.setBlock(x + 6, y + 1, z + 10, OPWeapons.condensedbodg, 14, 3);
		world.setBlock(x + 6, y + 1, z + 9, Blocks.air, 0, 3);
		world.setBlock(x + 6, y + 1, z + 8, Blocks.air, 0, 3);
		world.setBlock(x + 6, y + 1, z + 7, Blocks.air, 0, 3);
		world.setBlock(x + 6, y + 1, z + 6, Blocks.air, 0, 3);
		world.setBlock(x + 6, y + 1, z + 5, Blocks.air, 0, 3);
		world.setBlock(x + 6, y + 1, z + 4, Blocks.air, 0, 3);
		world.setBlock(x + 6, y + 1, z + 3, Blocks.air, 0, 3);
		world.setBlock(x + 6, y + 1, z + 2, Blocks.air, 0, 3);
		world.setBlock(x + 6, y + 1, z + 1, OPWeapons.condensedbodg, 14, 3);
		world.setBlock(x + 6, y + 1, z + 0, Blocks.air, 0, 3);
		world.setBlock(x + 7, y + 1, z + 11, Blocks.air, 0, 3);
		world.setBlock(x + 7, y + 1, z + 10, OPWeapons.condensedbodg, 14, 3);
		world.setBlock(x + 7, y + 1, z + 9, Blocks.air, 0, 3);
		//world.setBlock(x + 7, y + 1, z + 8, OPWeapons.OPcraftingstation, 0, 3);
		world.setBlock(x + 7, y + 1, z + 7, OPWeapons.OPcraftingstation, 0, 3);
		//world.setBlock(x + 7, y + 1, z + 6, Blocks.chest, 2, 3);
		//world.setBlock(x + 7, y + 1, z + 5, Blocks.chest, 2, 3);
		world.setBlock(x + 7, y + 1, z + 4, Blocks.crafting_table, 0, 3);
		//world.setBlock(x + 7, y + 1, z + 3, Blocks.furnace, 2, 3);
		
		world.setBlock(x + 7, y + 1, z + 1, OPWeapons.condensedbodg, 14, 3);
		world.setBlock(x + 7, y + 1, z + 0, Blocks.air, 0, 3);
		world.setBlock(x + 8, y + 1, z + 11, Blocks.air, 0, 3);
		world.setBlock(x + 8, y + 1, z + 10, OPWeapons.condensedbodg, 14, 3);
		world.setBlock(x + 8, y + 1, z + 9, OPWeapons.condensedbodg, 14, 3);
		world.setBlock(x + 8, y + 1, z + 8, OPWeapons.condensedbodg, 14, 3);
		world.setBlock(x + 8, y + 1, z + 7, OPWeapons.condensedbodg, 14, 3);
		world.setBlock(x + 8, y + 1, z + 6, OPWeapons.condensedbodg, 14, 3);
		world.setBlock(x + 8, y + 1, z + 5, OPWeapons.condensedbodg, 14, 3);
		world.setBlock(x + 8, y + 1, z + 4, OPWeapons.condensedbodg, 14, 3);
		world.setBlock(x + 8, y + 1, z + 3, OPWeapons.condensedbodg, 14, 3);
		world.setBlock(x + 8, y + 1, z + 2, OPWeapons.condensedbodg, 14, 3);
		world.setBlock(x + 8, y + 1, z + 1, OPWeapons.condensedbodg, 14, 3);
		world.setBlock(x + 8, y + 1, z + 0, Blocks.air, 0, 3);
		world.setBlock(x + 9, y + 1, z + 11, Blocks.nether_brick_fence, 0, 3);
		world.setBlock(x + 9, y + 1, z + 10, Blocks.air, 0, 3);
		world.setBlock(x + 9, y + 1, z + 9, Blocks.air, 0, 3);
		world.setBlock(x + 9, y + 1, z + 8, Blocks.air, 0, 3);
		world.setBlock(x + 9, y + 1, z + 7, Blocks.air, 0, 3);
		world.setBlock(x + 9, y + 1, z + 6, Blocks.air, 0, 3);
		world.setBlock(x + 9, y + 1, z + 5, Blocks.air, 0, 3);
		world.setBlock(x + 9, y + 1, z + 4, Blocks.air, 0, 3);
		world.setBlock(x + 9, y + 1, z + 3, Blocks.air, 0, 3);
		world.setBlock(x + 9, y + 1, z + 2, Blocks.air, 0, 3);
		world.setBlock(x + 9, y + 1, z + 1, Blocks.air, 0, 3);
		world.setBlock(x + 9, y + 1, z + 0, Blocks.nether_brick_fence, 0, 3);
		world.setBlock(x + 0, y + 2, z + 11, Blocks.air, 0, 3);
		world.setBlock(x + 0, y + 2, z + 10, Blocks.air, 0, 3);
		world.setBlock(x + 0, y + 2, z + 9, Blocks.air, 0, 3);
		world.setBlock(x + 0, y + 2, z + 8, Blocks.air, 0, 3);
		world.setBlock(x + 0, y + 2, z + 6, Blocks.air, 0, 3);
		world.setBlock(x + 0, y + 2, z + 5, Blocks.air, 0, 3);
		world.setBlock(x + 0, y + 2, z + 3, Blocks.air, 0, 3);
		world.setBlock(x + 0, y + 2, z + 2, Blocks.air, 0, 3);
		world.setBlock(x + 0, y + 2, z + 1, Blocks.air, 0, 3);
		world.setBlock(x + 0, y + 2, z + 0, Blocks.air, 0, 3);
		world.setBlock(x + 1, y + 2, z + 11, Blocks.nether_brick_fence, 0, 3);
		world.setBlock(x + 1, y + 2, z + 10, Blocks.air, 0, 3);
		world.setBlock(x + 1, y + 2, z + 9, Blocks.air, 0, 3);
		world.setBlock(x + 1, y + 2, z + 8, Blocks.air, 0, 3);
		world.setBlock(x + 1, y + 2, z + 7, OPWeapons.condensedbodg, 14, 3);
		world.setBlock(x + 1, y + 2, z + 6, Blocks.air, 0, 3);
		world.setBlock(x + 1, y + 2, z + 5, Blocks.air, 0, 3);
		world.setBlock(x + 1, y + 2, z + 4, OPWeapons.condensedbodg, 14, 3);
		world.setBlock(x + 1, y + 2, z + 3, Blocks.air, 0, 3);
		world.setBlock(x + 1, y + 2, z + 2, Blocks.air, 0, 3);
		world.setBlock(x + 1, y + 2, z + 1, Blocks.air, 0, 3);
		world.setBlock(x + 1, y + 2, z + 0, Blocks.nether_brick_fence, 0, 3);
		world.setBlock(x + 2, y + 2, z + 11, Blocks.air, 0, 3);
		world.setBlock(x + 2, y + 2, z + 10, OPWeapons.condensedbodg, 14, 3);
		world.setBlock(x + 2, y + 2, z + 9, Blocks.glass, 0, 3);
		world.setBlock(x + 2, y + 2, z + 8, Blocks.glass, 0, 3);
		world.setBlock(x + 2, y + 2, z + 7, Blocks.air, 0, 3);
		world.setBlock(x + 2, y + 2, z + 6, Blocks.air, 0, 3);
		world.setBlock(x + 2, y + 2, z + 5, Blocks.air, 0, 3);
		world.setBlock(x + 2, y + 2, z + 4, Blocks.air, 0, 3);
		world.setBlock(x + 2, y + 2, z + 3, Blocks.glass, 0, 3);
		world.setBlock(x + 2, y + 2, z + 2, Blocks.glass, 0, 3);
		world.setBlock(x + 2, y + 2, z + 1, OPWeapons.condensedbodg, 14, 3);
		world.setBlock(x + 2, y + 2, z + 0, Blocks.air, 0, 3);
		world.setBlock(x + 3, y + 2, z + 11, Blocks.air, 0, 3);
		world.setBlock(x + 3, y + 2, z + 10, Blocks.glass, 0, 3);
		world.setBlock(x + 3, y + 2, z + 9, Blocks.air, 0, 3);
		world.setBlock(x + 3, y + 2, z + 8, Blocks.air, 0, 3);
		world.setBlock(x + 3, y + 2, z + 7, Blocks.air, 0, 3);
		world.setBlock(x + 3, y + 2, z + 6, Blocks.air, 0, 3);
		world.setBlock(x + 3, y + 2, z + 5, Blocks.air, 0, 3);
		world.setBlock(x + 3, y + 2, z + 4, Blocks.air, 0, 3);
		world.setBlock(x + 3, y + 2, z + 3, Blocks.air, 0, 3);
		world.setBlock(x + 3, y + 2, z + 2, Blocks.air, 0, 3);
		world.setBlock(x + 3, y + 2, z + 1, Blocks.glass, 0, 3);
		world.setBlock(x + 3, y + 2, z + 0, Blocks.air, 0, 3);
		world.setBlock(x + 4, y + 2, z + 11, Blocks.air, 0, 3);
		world.setBlock(x + 4, y + 2, z + 10, Blocks.glass, 0, 3);
		world.setBlock(x + 4, y + 2, z + 9, Blocks.air, 0, 3);
		world.setBlock(x + 4, y + 2, z + 8, Blocks.air, 0, 3);
		world.setBlock(x + 4, y + 2, z + 7, Blocks.air, 0, 3);
		world.setBlock(x + 4, y + 2, z + 6, Blocks.air, 0, 3);
		world.setBlock(x + 4, y + 2, z + 5, Blocks.air, 0, 3);
		world.setBlock(x + 4, y + 2, z + 4, Blocks.air, 0, 3);
		world.setBlock(x + 4, y + 2, z + 3, Blocks.air, 0, 3);
		world.setBlock(x + 4, y + 2, z + 2, Blocks.carpet, 7, 3);
		world.setBlock(x + 4, y + 2, z + 1, Blocks.glass, 0, 3);
		world.setBlock(x + 4, y + 2, z + 0, Blocks.air, 0, 3);
		world.setBlock(x + 5, y + 2, z + 11, Blocks.air, 0, 3);
		
		world.setBlock(x + 5, y + 2, z + 9, Blocks.air, 0, 3);
		world.setBlock(x + 5, y + 2, z + 8, Blocks.air, 0, 3);
		world.setBlock(x + 5, y + 2, z + 7, Blocks.air, 0, 3);
		world.setBlock(x + 5, y + 2, z + 6, Blocks.air, 0, 3);
		world.setBlock(x + 5, y + 2, z + 5, Blocks.air, 0, 3);
		world.setBlock(x + 5, y + 2, z + 4, Blocks.air, 0, 3);
		world.setBlock(x + 5, y + 2, z + 3, Blocks.air, 0, 3);
		world.setBlock(x + 5, y + 2, z + 2, Blocks.air, 0, 3);
		world.setBlock(x + 5, y + 2, z + 1, Blocks.glass, 0, 3);
		world.setBlock(x + 5, y + 2, z + 0, Blocks.air, 0, 3);
		world.setBlock(x + 6, y + 2, z + 11, Blocks.air, 0, 3);
		world.setBlock(x + 6, y + 2, z + 10, Blocks.glass, 0, 3);
		world.setBlock(x + 6, y + 2, z + 9, Blocks.air, 0, 3);
		world.setBlock(x + 6, y + 2, z + 8, Blocks.air, 0, 3);
		world.setBlock(x + 6, y + 2, z + 7, Blocks.air, 0, 3);
		world.setBlock(x + 6, y + 2, z + 6, Blocks.air, 0, 3);
		world.setBlock(x + 6, y + 2, z + 5, Blocks.air, 0, 3);
		world.setBlock(x + 6, y + 2, z + 4, Blocks.air, 0, 3);
		world.setBlock(x + 6, y + 2, z + 3, Blocks.air, 0, 3);
		world.setBlock(x + 6, y + 2, z + 2, Blocks.air, 0, 3);
		world.setBlock(x + 6, y + 2, z + 1, Blocks.glass, 0, 3);
		world.setBlock(x + 6, y + 2, z + 0, Blocks.air, 0, 3);
		world.setBlock(x + 7, y + 2, z + 11, Blocks.air, 0, 3);
		
		world.setBlock(x + 7, y + 2, z + 9, Blocks.air, 0, 3);
		world.setBlock(x + 7, y + 2, z + 8, Blocks.air, 0, 3);
		world.setBlock(x + 7, y + 2, z + 7, Blocks.air, 0, 3);
		world.setBlock(x + 7, y + 2, z + 6, Blocks.air, 0, 3);
		world.setBlock(x + 7, y + 2, z + 5, Blocks.air, 0, 3);
		
		world.setBlock(x + 7, y + 2, z + 3, Blocks.air, 0, 3);
		world.setBlock(x + 7, y + 2, z + 2, Blocks.air, 0, 3);
		world.setBlock(x + 7, y + 2, z + 1, Blocks.glass, 0, 3);
		world.setBlock(x + 7, y + 2, z + 0, Blocks.air, 0, 3);
		world.setBlock(x + 8, y + 2, z + 11, Blocks.air, 0, 3);
		world.setBlock(x + 8, y + 2, z + 10, OPWeapons.condensedbodg, 14, 3);
		world.setBlock(x + 8, y + 2, z + 9, OPWeapons.condensedbodg, 14, 3);
		world.setBlock(x + 8, y + 2, z + 8, OPWeapons.condensedbodg, 14, 3);
		world.setBlock(x + 8, y + 2, z + 7, OPWeapons.condensedbodg, 14, 3);
		world.setBlock(x + 8, y + 2, z + 6, OPWeapons.condensedbodg, 14, 3);
		world.setBlock(x + 8, y + 2, z + 5, OPWeapons.condensedbodg, 14, 3);
		world.setBlock(x + 8, y + 2, z + 4, OPWeapons.condensedbodg, 14, 3);
		world.setBlock(x + 8, y + 2, z + 3, OPWeapons.condensedbodg, 14, 3);
		world.setBlock(x + 8, y + 2, z + 2, OPWeapons.condensedbodg, 14, 3);
		world.setBlock(x + 8, y + 2, z + 1, OPWeapons.condensedbodg, 14, 3);
		world.setBlock(x + 8, y + 2, z + 0, Blocks.air, 0, 3);
		world.setBlock(x + 9, y + 2, z + 11, Blocks.nether_brick_fence, 0, 3);
		world.setBlock(x + 9, y + 2, z + 10, Blocks.air, 0, 3);
		world.setBlock(x + 9, y + 2, z + 9, Blocks.air, 0, 3);
		world.setBlock(x + 9, y + 2, z + 8, Blocks.air, 0, 3);
		world.setBlock(x + 9, y + 2, z + 7, Blocks.air, 0, 3);
		world.setBlock(x + 9, y + 2, z + 6, Blocks.air, 0, 3);
		world.setBlock(x + 9, y + 2, z + 5, Blocks.air, 0, 3);
		world.setBlock(x + 9, y + 2, z + 4, Blocks.air, 0, 3);
		world.setBlock(x + 9, y + 2, z + 3, Blocks.air, 0, 3);
		world.setBlock(x + 9, y + 2, z + 2, Blocks.air, 0, 3);
		world.setBlock(x + 9, y + 2, z + 1, Blocks.air, 0, 3);
		world.setBlock(x + 9, y + 2, z + 0, Blocks.nether_brick_fence, 0, 3);
		world.setBlock(x + 0, y + 3, z + 11, Blocks.air, 0, 3);
		world.setBlock(x + 0, y + 3, z + 10, Blocks.air, 0, 3);
		world.setBlock(x + 0, y + 3, z + 9, Blocks.air, 0, 3);
		world.setBlock(x + 0, y + 3, z + 8, Blocks.air, 0, 3);
		world.setBlock(x + 0, y + 3, z + 7, Blocks.air, 0, 3);
		world.setBlock(x + 0, y + 3, z + 6, Blocks.air, 0, 3);
		world.setBlock(x + 0, y + 3, z + 5, Blocks.air, 0, 3);
		world.setBlock(x + 0, y + 3, z + 4, Blocks.air, 0, 3);
		world.setBlock(x + 0, y + 3, z + 3, Blocks.air, 0, 3);
		world.setBlock(x + 0, y + 3, z + 2, Blocks.air, 0, 3);
		world.setBlock(x + 0, y + 3, z + 1, Blocks.air, 0, 3);
		world.setBlock(x + 0, y + 3, z + 0, Blocks.air, 0, 3);
		world.setBlock(x + 1, y + 3, z + 11, Blocks.nether_brick_fence, 0, 3);
		world.setBlock(x + 1, y + 3, z + 10, Blocks.air, 0, 3);
		world.setBlock(x + 1, y + 3, z + 9, Blocks.air, 0, 3);
		world.setBlock(x + 1, y + 3, z + 8, Blocks.air, 0, 3);
		world.setBlock(x + 1, y + 3, z + 7, OPWeapons.condensedbodg, 14, 3);
		world.setBlock(x + 1, y + 3, z + 6, OPWeapons.condensedbodg, 14, 3);
		world.setBlock(x + 1, y + 3, z + 5, OPWeapons.condensedbodg, 14, 3);
		world.setBlock(x + 1, y + 3, z + 4, OPWeapons.condensedbodg, 14, 3);
		world.setBlock(x + 1, y + 3, z + 3, Blocks.air, 0, 3);
		world.setBlock(x + 1, y + 3, z + 2, Blocks.air, 0, 3);
		world.setBlock(x + 1, y + 3, z + 1, Blocks.air, 0, 3);
		world.setBlock(x + 1, y + 3, z + 0, Blocks.nether_brick_fence, 0, 3);
		world.setBlock(x + 2, y + 3, z + 11, Blocks.air, 0, 3);
		world.setBlock(x + 2, y + 3, z + 10, OPWeapons.condensedbodg, 14, 3);
		world.setBlock(x + 2, y + 3, z + 9, OPWeapons.condensedbodg, 14, 3);
		world.setBlock(x + 2, y + 3, z + 8, OPWeapons.condensedbodg, 14, 3);
		world.setBlock(x + 2, y + 3, z + 7, Blocks.air, 0, 3);
		world.setBlock(x + 2, y + 3, z + 6, Blocks.air, 0, 3);
		world.setBlock(x + 2, y + 3, z + 5, Blocks.air, 0, 3);
		world.setBlock(x + 2, y + 3, z + 4, Blocks.air, 0, 3);
		world.setBlock(x + 2, y + 3, z + 3, OPWeapons.condensedbodg, 14, 3);
		world.setBlock(x + 2, y + 3, z + 2, OPWeapons.condensedbodg, 14, 3);
		world.setBlock(x + 2, y + 3, z + 1, OPWeapons.condensedbodg, 14, 3);
		world.setBlock(x + 2, y + 3, z + 0, Blocks.air, 0, 3);
		world.setBlock(x + 3, y + 3, z + 11, Blocks.air, 0, 3);
		world.setBlock(x + 3, y + 3, z + 10, OPWeapons.condensedbodg, 14, 3);
		world.setBlock(x + 3, y + 3, z + 9, Blocks.air, 0, 3);
		world.setBlock(x + 3, y + 3, z + 8, Blocks.air, 0, 3);
		world.setBlock(x + 3, y + 3, z + 7, Blocks.air, 0, 3);
		world.setBlock(x + 3, y + 3, z + 6, Blocks.air, 0, 3);
		world.setBlock(x + 3, y + 3, z + 5, Blocks.air, 0, 3);
		world.setBlock(x + 3, y + 3, z + 4, Blocks.air, 0, 3);
		world.setBlock(x + 3, y + 3, z + 3, Blocks.air, 0, 3);
		world.setBlock(x + 3, y + 3, z + 2, Blocks.air, 0, 3);
		world.setBlock(x + 3, y + 3, z + 1, OPWeapons.condensedbodg, 14, 3);
		world.setBlock(x + 3, y + 3, z + 0, Blocks.air, 0, 3);
		world.setBlock(x + 4, y + 3, z + 11, Blocks.air, 0, 3);
		world.setBlock(x + 4, y + 3, z + 10, OPWeapons.condensedbodg, 14, 3);
		world.setBlock(x + 4, y + 3, z + 9, Blocks.air, 0, 3);
		world.setBlock(x + 4, y + 3, z + 8, Blocks.air, 0, 3);
		world.setBlock(x + 4, y + 3, z + 7, Blocks.air, 0, 3);
		world.setBlock(x + 4, y + 3, z + 6, Blocks.air, 0, 3);
		world.setBlock(x + 4, y + 3, z + 5, Blocks.air, 0, 3);
		world.setBlock(x + 4, y + 3, z + 4, Blocks.air, 0, 3);
		world.setBlock(x + 4, y + 3, z + 3, Blocks.air, 0, 3);
		world.setBlock(x + 4, y + 3, z + 2, Blocks.air, 0, 3);
		world.setBlock(x + 4, y + 3, z + 1, OPWeapons.condensedbodg, 14, 3);
		world.setBlock(x + 4, y + 3, z + 0, Blocks.air, 0, 3);
		world.setBlock(x + 5, y + 3, z + 11, Blocks.air, 0, 3);
		world.setBlock(x + 5, y + 3, z + 10, OPWeapons.condensedbodg, 14, 3);
		world.setBlock(x + 5, y + 3, z + 9, Blocks.air, 0, 3);
		world.setBlock(x + 5, y + 3, z + 8, Blocks.air, 0, 3);
		world.setBlock(x + 5, y + 3, z + 7, Blocks.air, 0, 3);
		world.setBlock(x + 5, y + 3, z + 6, Blocks.air, 0, 3);
		world.setBlock(x + 5, y + 3, z + 5, Blocks.air, 0, 3);
		world.setBlock(x + 5, y + 3, z + 4, Blocks.air, 0, 3);
		world.setBlock(x + 5, y + 3, z + 3, Blocks.air, 0, 3);
		world.setBlock(x + 5, y + 3, z + 2, Blocks.air, 0, 3);
		world.setBlock(x + 5, y + 3, z + 1, OPWeapons.condensedbodg, 14, 3);
		world.setBlock(x + 5, y + 3, z + 0, Blocks.air, 0, 3);
		world.setBlock(x + 6, y + 3, z + 11, Blocks.air, 0, 3);
		world.setBlock(x + 6, y + 3, z + 10, OPWeapons.condensedbodg, 14, 3);
		world.setBlock(x + 6, y + 3, z + 9, Blocks.air, 0, 3);
		world.setBlock(x + 6, y + 3, z + 8, Blocks.air, 0, 3);
		world.setBlock(x + 6, y + 3, z + 7, Blocks.air, 0, 3);
		world.setBlock(x + 6, y + 3, z + 6, Blocks.air, 0, 3);
		world.setBlock(x + 6, y + 3, z + 5, Blocks.air, 0, 3);
		world.setBlock(x + 6, y + 3, z + 4, Blocks.air, 0, 3);
		world.setBlock(x + 6, y + 3, z + 3, Blocks.air, 0, 3);
		world.setBlock(x + 6, y + 3, z + 2, Blocks.air, 0, 3);
		world.setBlock(x + 6, y + 3, z + 1, OPWeapons.condensedbodg, 14, 3);
		world.setBlock(x + 6, y + 3, z + 0, Blocks.air, 0, 3);
		world.setBlock(x + 7, y + 3, z + 11, Blocks.air, 0, 3);
		world.setBlock(x + 7, y + 3, z + 10, OPWeapons.condensedbodg, 14, 3);
		world.setBlock(x + 7, y + 3, z + 9, Blocks.air, 0, 3);
		world.setBlock(x + 7, y + 3, z + 8, Blocks.air, 0, 3);
		world.setBlock(x + 7, y + 3, z + 7, Blocks.air, 0, 3);
		world.setBlock(x + 7, y + 3, z + 6, Blocks.air, 0, 3);
		world.setBlock(x + 7, y + 3, z + 5, Blocks.air, 0, 3);
		world.setBlock(x + 7, y + 3, z + 4, Blocks.air, 0, 3);
		world.setBlock(x + 7, y + 3, z + 3, Blocks.air, 0, 3);
		world.setBlock(x + 7, y + 3, z + 2, Blocks.air, 0, 3);
		world.setBlock(x + 7, y + 3, z + 1, OPWeapons.condensedbodg, 14, 3);
		world.setBlock(x + 7, y + 3, z + 0, Blocks.air, 0, 3);
		world.setBlock(x + 8, y + 3, z + 11, Blocks.air, 0, 3);
		world.setBlock(x + 8, y + 3, z + 10, OPWeapons.condensedbodg, 14, 3);
		world.setBlock(x + 8, y + 3, z + 9, OPWeapons.condensedbodg, 14, 3);
		world.setBlock(x + 8, y + 3, z + 8, OPWeapons.condensedbodg, 14, 3);
		world.setBlock(x + 8, y + 3, z + 7, OPWeapons.condensedbodg, 14, 3);
		world.setBlock(x + 8, y + 3, z + 6, OPWeapons.condensedbodg, 14, 3);
		world.setBlock(x + 8, y + 3, z + 5, OPWeapons.condensedbodg, 14, 3);
		world.setBlock(x + 8, y + 3, z + 4, OPWeapons.condensedbodg, 14, 3);
		world.setBlock(x + 8, y + 3, z + 3, OPWeapons.condensedbodg, 14, 3);
		world.setBlock(x + 8, y + 3, z + 2, OPWeapons.condensedbodg, 14, 3);
		world.setBlock(x + 8, y + 3, z + 1, OPWeapons.condensedbodg, 14, 3);
		world.setBlock(x + 8, y + 3, z + 0, Blocks.air, 0, 3);
		world.setBlock(x + 9, y + 3, z + 11, Blocks.nether_brick_fence, 0, 3);
		world.setBlock(x + 9, y + 3, z + 10, Blocks.air, 0, 3);
		world.setBlock(x + 9, y + 3, z + 9, Blocks.air, 0, 3);
		world.setBlock(x + 9, y + 3, z + 8, Blocks.air, 0, 3);
		world.setBlock(x + 9, y + 3, z + 7, Blocks.air, 0, 3);
		world.setBlock(x + 9, y + 3, z + 6, Blocks.air, 0, 3);
		world.setBlock(x + 9, y + 3, z + 5, Blocks.air, 0, 3);
		world.setBlock(x + 9, y + 3, z + 4, Blocks.air, 0, 3);
		world.setBlock(x + 9, y + 3, z + 3, Blocks.air, 0, 3);
		world.setBlock(x + 9, y + 3, z + 2, Blocks.air, 0, 3);
		world.setBlock(x + 9, y + 3, z + 1, Blocks.air, 0, 3);
		world.setBlock(x + 9, y + 3, z + 0, Blocks.nether_brick_fence, 0, 3);
		world.setBlock(x + 0, y + 4, z + 11, Blocks.air, 0, 3);
		world.setBlock(x + 0, y + 4, z + 10, Blocks.air, 0, 3);
		world.setBlock(x + 0, y + 4, z + 9, Blocks.air, 0, 3);
		world.setBlock(x + 0, y + 4, z + 8, Blocks.air, 0, 3);
		world.setBlock(x + 0, y + 4, z + 7, Blocks.air, 0, 3);
		world.setBlock(x + 0, y + 4, z + 6, Blocks.air, 0, 3);
		world.setBlock(x + 0, y + 4, z + 5, Blocks.air, 0, 3);
		world.setBlock(x + 0, y + 4, z + 4, Blocks.air, 0, 3);
		world.setBlock(x + 0, y + 4, z + 3, Blocks.air, 0, 3);
		world.setBlock(x + 0, y + 4, z + 2, Blocks.air, 0, 3);
		world.setBlock(x + 0, y + 4, z + 1, Blocks.air, 0, 3);
		world.setBlock(x + 0, y + 4, z + 0, Blocks.air, 0, 3);
		world.setBlock(x + 1, y + 4, z + 11, Blocks.nether_brick_stairs, 0, 3);
		world.setBlock(x + 1, y + 4, z + 10, Blocks.nether_brick_stairs, 0, 3);
		world.setBlock(x + 1, y + 4, z + 9, Blocks.nether_brick_stairs, 0, 3);
		world.setBlock(x + 1, y + 4, z + 8, Blocks.nether_brick_stairs, 0, 3);
		world.setBlock(x + 1, y + 4, z + 7, OPWeapons.demonLight, 0, 3);
		world.setBlock(x + 1, y + 4, z + 6, OPWeapons.condensedbodg, 14, 3);
		world.setBlock(x + 1, y + 4, z + 5, OPWeapons.condensedbodg, 14, 3);
		world.setBlock(x + 1, y + 4, z + 4, OPWeapons.demonLight, 0, 3);
		world.setBlock(x + 1, y + 4, z + 3, Blocks.nether_brick_stairs, 0, 3);
		world.setBlock(x + 1, y + 4, z + 2, Blocks.nether_brick_stairs, 0, 3);
		world.setBlock(x + 1, y + 4, z + 1, Blocks.nether_brick_stairs, 0, 3);
		world.setBlock(x + 1, y + 4, z + 0, Blocks.nether_brick_stairs, 2, 3);
		world.setBlock(x + 2, y + 4, z + 11, Blocks.nether_brick_stairs, 3, 3);
		world.setBlock(x + 2, y + 4, z + 10, OPWeapons.condensedbodg, 14, 3);
		world.setBlock(x + 2, y + 4, z + 9, OPWeapons.condensedbodg, 14, 3);
		world.setBlock(x + 2, y + 4, z + 8, OPWeapons.condensedbodg, 14, 3);
		world.setBlock(x + 2, y + 4, z + 7, OPWeapons.condensedbodg, 14, 3);
		world.setBlock(x + 2, y + 4, z + 6, OPWeapons.condensedbodg, 14, 3);
		world.setBlock(x + 2, y + 4, z + 5, OPWeapons.condensedbodg, 14, 3);
		world.setBlock(x + 2, y + 4, z + 4, OPWeapons.condensedbodg, 14, 3);
		world.setBlock(x + 2, y + 4, z + 3, OPWeapons.condensedbodg, 14, 3);
		world.setBlock(x + 2, y + 4, z + 2, OPWeapons.condensedbodg, 14, 3);
		world.setBlock(x + 2, y + 4, z + 1, OPWeapons.condensedbodg, 14, 3);
		world.setBlock(x + 2, y + 4, z + 0, Blocks.nether_brick_stairs, 2, 3);
		world.setBlock(x + 3, y + 4, z + 11, Blocks.nether_brick_stairs, 3, 3);
		world.setBlock(x + 3, y + 4, z + 10, OPWeapons.condensedbodg, 14, 3);
		world.setBlock(x + 3, y + 4, z + 9, OPWeapons.condensedbodg, 14, 3);
		world.setBlock(x + 3, y + 4, z + 8, OPWeapons.condensedbodg, 14, 3);
		world.setBlock(x + 3, y + 4, z + 7, OPWeapons.condensedbodg, 14, 3);
		world.setBlock(x + 3, y + 4, z + 6, OPWeapons.condensedbodg, 14, 3);
		world.setBlock(x + 3, y + 4, z + 5, OPWeapons.condensedbodg, 14, 3);
		world.setBlock(x + 3, y + 4, z + 4, OPWeapons.condensedbodg, 14, 3);
		world.setBlock(x + 3, y + 4, z + 3, OPWeapons.condensedbodg, 14, 3);
		world.setBlock(x + 3, y + 4, z + 2, OPWeapons.condensedbodg, 14, 3);
		world.setBlock(x + 3, y + 4, z + 1, OPWeapons.condensedbodg, 14, 3);
		world.setBlock(x + 3, y + 4, z + 0, Blocks.nether_brick_stairs, 2, 3);
		world.setBlock(x + 4, y + 4, z + 11, Blocks.nether_brick_stairs, 3, 3);
		world.setBlock(x + 4, y + 4, z + 10, OPWeapons.condensedbodg, 14, 3);
		world.setBlock(x + 4, y + 4, z + 9, OPWeapons.condensedbodg, 14, 3);
		world.setBlock(x + 4, y + 4, z + 8, OPWeapons.condensedbodg, 14, 3);
		world.setBlock(x + 4, y + 4, z + 7, OPWeapons.condensedbodg, 14, 3);
		world.setBlock(x + 4, y + 4, z + 6, OPWeapons.demonLight, 0, 3);
		
		world.setBlock(x + 4, y + 4, z + 4, OPWeapons.condensedbodg, 14, 3);
		world.setBlock(x + 4, y + 4, z + 3, OPWeapons.condensedbodg, 14, 3);
		world.setBlock(x + 4, y + 4, z + 2, OPWeapons.condensedbodg, 14, 3);
		world.setBlock(x + 4, y + 4, z + 1, OPWeapons.condensedbodg, 14, 3);
		world.setBlock(x + 4, y + 4, z + 0, Blocks.nether_brick_stairs, 2, 3);
		world.setBlock(x + 5, y + 4, z + 11, Blocks.nether_brick_stairs, 3, 3);
		world.setBlock(x + 5, y + 4, z + 10, OPWeapons.condensedbodg, 14, 3);
		world.setBlock(x + 5, y + 4, z + 9, OPWeapons.condensedbodg, 14, 3);
		world.setBlock(x + 5, y + 4, z + 8, OPWeapons.condensedbodg, 14, 3);
		world.setBlock(x + 5, y + 4, z + 7, OPWeapons.condensedbodg, 14, 3);
		world.setBlock(x + 5, y + 4, z + 6, OPWeapons.demonLight, 0, 3);
		world.setBlock(x + 5, y + 4, z + 5, OPWeapons.demonLight, 0, 3);
		world.setBlock(x + 5, y + 4, z + 4, OPWeapons.condensedbodg, 14, 3);
		world.setBlock(x + 5, y + 4, z + 3, OPWeapons.condensedbodg, 14, 3);
		world.setBlock(x + 5, y + 4, z + 2, OPWeapons.condensedbodg, 14, 3);
		world.setBlock(x + 5, y + 4, z + 1, OPWeapons.condensedbodg, 14, 3);
		world.setBlock(x + 5, y + 4, z + 0, Blocks.nether_brick_stairs, 2, 3);
		world.setBlock(x + 6, y + 4, z + 11, Blocks.nether_brick_stairs, 3, 3);
		world.setBlock(x + 6, y + 4, z + 10, OPWeapons.condensedbodg, 14, 3);
		world.setBlock(x + 6, y + 4, z + 9, OPWeapons.condensedbodg, 14, 3);
		world.setBlock(x + 6, y + 4, z + 8, OPWeapons.condensedbodg, 14, 3);
		world.setBlock(x + 6, y + 4, z + 7, OPWeapons.condensedbodg, 14, 3);
		world.setBlock(x + 6, y + 4, z + 6, OPWeapons.condensedbodg, 14, 3);
		world.setBlock(x + 6, y + 4, z + 5, OPWeapons.condensedbodg, 14, 3);
		world.setBlock(x + 6, y + 4, z + 4, OPWeapons.condensedbodg, 14, 3);
		world.setBlock(x + 6, y + 4, z + 3, OPWeapons.condensedbodg, 14, 3);
		world.setBlock(x + 6, y + 4, z + 2, OPWeapons.condensedbodg, 14, 3);
		world.setBlock(x + 6, y + 4, z + 1, OPWeapons.condensedbodg, 14, 3);
		world.setBlock(x + 6, y + 4, z + 0, Blocks.nether_brick_stairs, 2, 3);
		world.setBlock(x + 7, y + 4, z + 11, Blocks.nether_brick_stairs, 3, 3);
		world.setBlock(x + 7, y + 4, z + 10, OPWeapons.condensedbodg, 14, 3);
		world.setBlock(x + 7, y + 4, z + 9, OPWeapons.condensedbodg, 14, 3);
		world.setBlock(x + 7, y + 4, z + 8, OPWeapons.condensedbodg, 14, 3);
		world.setBlock(x + 7, y + 4, z + 7, OPWeapons.condensedbodg, 14, 3);
		world.setBlock(x + 7, y + 4, z + 6, OPWeapons.condensedbodg, 14, 3);
		world.setBlock(x + 7, y + 4, z + 5, OPWeapons.condensedbodg, 14, 3);
		world.setBlock(x + 7, y + 4, z + 4, OPWeapons.condensedbodg, 14, 3);
		world.setBlock(x + 7, y + 4, z + 3, OPWeapons.condensedbodg, 14, 3);
		world.setBlock(x + 7, y + 4, z + 2, OPWeapons.condensedbodg, 14, 3);
		world.setBlock(x + 7, y + 4, z + 1, OPWeapons.condensedbodg, 14, 3);
		world.setBlock(x + 7, y + 4, z + 0, Blocks.nether_brick_stairs, 2, 3);
		world.setBlock(x + 8, y + 4, z + 11, Blocks.nether_brick_stairs, 3, 3);
		world.setBlock(x + 8, y + 4, z + 10, OPWeapons.condensedbodg, 14, 3);
		world.setBlock(x + 8, y + 4, z + 9, OPWeapons.condensedbodg, 14, 3);
		world.setBlock(x + 8, y + 4, z + 8, OPWeapons.condensedbodg, 14, 3);
		world.setBlock(x + 8, y + 4, z + 7, OPWeapons.condensedbodg, 14, 3);
		world.setBlock(x + 8, y + 4, z + 6, OPWeapons.condensedbodg, 14, 3);
		world.setBlock(x + 8, y + 4, z + 5, OPWeapons.condensedbodg, 14, 3);
		world.setBlock(x + 8, y + 4, z + 4, OPWeapons.condensedbodg, 14, 3);
		world.setBlock(x + 8, y + 4, z + 3, OPWeapons.condensedbodg, 14, 3);
		world.setBlock(x + 8, y + 4, z + 2, OPWeapons.condensedbodg, 14, 3);
		world.setBlock(x + 8, y + 4, z + 1, OPWeapons.condensedbodg, 14, 3);
		world.setBlock(x + 8, y + 4, z + 0, Blocks.nether_brick_stairs, 2, 3);
		world.setBlock(x + 9, y + 4, z + 11, Blocks.nether_brick_stairs, 3, 3);
		world.setBlock(x + 9, y + 4, z + 10, Blocks.nether_brick_stairs, 1, 3);
		world.setBlock(x + 9, y + 4, z + 9, Blocks.nether_brick_stairs, 1, 3);
		world.setBlock(x + 9, y + 4, z + 8, Blocks.nether_brick_stairs, 1, 3);
		world.setBlock(x + 9, y + 4, z + 7, Blocks.nether_brick_stairs, 1, 3);
		world.setBlock(x + 9, y + 4, z + 6, Blocks.nether_brick_stairs, 1, 3);
		world.setBlock(x + 9, y + 4, z + 5, Blocks.nether_brick_stairs, 1, 3);
		world.setBlock(x + 9, y + 4, z + 4, Blocks.nether_brick_stairs, 1, 3);
		world.setBlock(x + 9, y + 4, z + 3, Blocks.nether_brick_stairs, 1, 3);
		world.setBlock(x + 9, y + 4, z + 2, Blocks.nether_brick_stairs, 1, 3);
		world.setBlock(x + 9, y + 4, z + 1, Blocks.nether_brick_stairs, 1, 3);
		world.setBlock(x + 9, y + 4, z + 0, Blocks.nether_brick_stairs, 1, 3);
		world.setBlock(x + 0, y + 5, z + 11, Blocks.air, 0, 3);
		world.setBlock(x + 0, y + 5, z + 10, Blocks.air, 0, 3);
		world.setBlock(x + 0, y + 5, z + 9, Blocks.air, 0, 3);
		world.setBlock(x + 0, y + 5, z + 8, Blocks.air, 0, 3);
		world.setBlock(x + 0, y + 5, z + 7, Blocks.air, 0, 3);
		world.setBlock(x + 0, y + 5, z + 6, Blocks.air, 0, 3);
		world.setBlock(x + 0, y + 5, z + 5, Blocks.air, 0, 3);
		world.setBlock(x + 0, y + 5, z + 4, Blocks.air, 0, 3);
		world.setBlock(x + 0, y + 5, z + 3, Blocks.air, 0, 3);
		world.setBlock(x + 0, y + 5, z + 2, Blocks.air, 0, 3);
		world.setBlock(x + 0, y + 5, z + 1, Blocks.air, 0, 3);
		world.setBlock(x + 0, y + 5, z + 0, Blocks.air, 0, 3);
		world.setBlock(x + 1, y + 5, z + 11, Blocks.air, 0, 3);
		world.setBlock(x + 1, y + 5, z + 10, Blocks.air, 0, 3);
		world.setBlock(x + 1, y + 5, z + 9, Blocks.air, 0, 3);
		world.setBlock(x + 1, y + 5, z + 8, Blocks.air, 0, 3);
		world.setBlock(x + 1, y + 5, z + 7, Blocks.air, 0, 3);
		world.setBlock(x + 1, y + 5, z + 6, Blocks.air, 0, 3);
		world.setBlock(x + 1, y + 5, z + 5, Blocks.air, 0, 3);
		world.setBlock(x + 1, y + 5, z + 4, Blocks.air, 0, 3);
		world.setBlock(x + 1, y + 5, z + 3, Blocks.air, 0, 3);
		world.setBlock(x + 1, y + 5, z + 2, Blocks.air, 0, 3);
		world.setBlock(x + 1, y + 5, z + 1, Blocks.air, 0, 3);
		world.setBlock(x + 1, y + 5, z + 0, Blocks.air, 0, 3);
		world.setBlock(x + 2, y + 5, z + 11, Blocks.air, 0, 3);
		world.setBlock(x + 2, y + 5, z + 10, Blocks.nether_brick_stairs, 3, 3);
		world.setBlock(x + 2, y + 5, z + 9, Blocks.nether_brick_stairs, 0, 3);
		world.setBlock(x + 2, y + 5, z + 8, Blocks.nether_brick_stairs, 0, 3);
		world.setBlock(x + 2, y + 5, z + 7, Blocks.nether_brick_stairs, 0, 3);
		world.setBlock(x + 2, y + 5, z + 6, Blocks.nether_brick_stairs, 0, 3);
		world.setBlock(x + 2, y + 5, z + 5, Blocks.nether_brick_stairs, 0, 3);
		world.setBlock(x + 2, y + 5, z + 4, Blocks.nether_brick_stairs, 0, 3);
		world.setBlock(x + 2, y + 5, z + 3, Blocks.nether_brick_stairs, 0, 3);
		world.setBlock(x + 2, y + 5, z + 2, Blocks.nether_brick_stairs, 0, 3);
		world.setBlock(x + 2, y + 5, z + 1, Blocks.nether_brick_stairs, 0, 3);
		world.setBlock(x + 2, y + 5, z + 0, Blocks.air, 0, 3);
		world.setBlock(x + 3, y + 5, z + 11, Blocks.air, 0, 3);
		world.setBlock(x + 3, y + 5, z + 10, Blocks.nether_brick_stairs, 3, 3);
		world.setBlock(x + 3, y + 5, z + 9, Blocks.nether_brick, 0, 3);
		world.setBlock(x + 3, y + 5, z + 8, Blocks.nether_brick, 0, 3);
		
		world.setBlock(x + 3, y + 5, z + 6, Blocks.nether_brick, 0, 3);
		world.setBlock(x + 3, y + 5, z + 5, Blocks.nether_brick, 0, 3);
		world.setBlock(x + 3, y + 5, z + 4, Blocks.nether_brick, 0, 3);
		world.setBlock(x + 3, y + 5, z + 3, Blocks.nether_brick, 0, 3);
		world.setBlock(x + 3, y + 5, z + 2, Blocks.nether_brick, 0, 3);
		world.setBlock(x + 3, y + 5, z + 1, Blocks.nether_brick_stairs, 2, 3);
		world.setBlock(x + 3, y + 5, z + 0, Blocks.air, 0, 3);
		world.setBlock(x + 4, y + 5, z + 11, Blocks.air, 0, 3);
		
		world.setBlock(x + 4, y + 5, z + 8, Blocks.nether_brick, 0, 3);
		world.setBlock(x + 4, y + 5, z + 7, Blocks.nether_brick, 0, 3);
		world.setBlock(x + 4, y + 5, z + 6, Blocks.nether_brick, 0, 3);
		world.setBlock(x + 4, y + 5, z + 5, Blocks.nether_brick, 0, 3);
		world.setBlock(x + 4, y + 5, z + 4, Blocks.nether_brick, 0, 3);
		world.setBlock(x + 4, y + 5, z + 3, Blocks.nether_brick, 0, 3);
		world.setBlock(x + 4, y + 5, z + 2, Blocks.nether_brick, 0, 3);
		world.setBlock(x + 4, y + 5, z + 1, Blocks.nether_brick_stairs, 2, 3);
		world.setBlock(x + 4, y + 5, z + 0, Blocks.air, 0, 3);
		world.setBlock(x + 5, y + 5, z + 11, Blocks.air, 0, 3);
		world.setBlock(x + 5, y + 5, z + 10, Blocks.nether_brick_stairs, 3, 3);
		world.setBlock(x + 5, y + 5, z + 9, Blocks.nether_brick, 0, 3);
		world.setBlock(x + 5, y + 5, z + 8, Blocks.nether_brick, 0, 3);
		world.setBlock(x + 5, y + 5, z + 7, Blocks.nether_brick, 0, 3);
		world.setBlock(x + 5, y + 5, z + 6, Blocks.nether_brick, 0, 3);
		world.setBlock(x + 5, y + 5, z + 5, Blocks.nether_brick, 0, 3);
		world.setBlock(x + 5, y + 5, z + 4, Blocks.nether_brick, 0, 3);
		world.setBlock(x + 5, y + 5, z + 3, Blocks.nether_brick, 0, 3);
		world.setBlock(x + 5, y + 5, z + 2, Blocks.nether_brick, 0, 3);
		world.setBlock(x + 5, y + 5, z + 1, Blocks.nether_brick_stairs, 2, 3);
		world.setBlock(x + 5, y + 5, z + 0, Blocks.air, 0, 3);
		world.setBlock(x + 6, y + 5, z + 11, Blocks.air, 0, 3);
		world.setBlock(x + 6, y + 5, z + 10, Blocks.nether_brick_stairs, 3, 3);
		world.setBlock(x + 6, y + 5, z + 9, Blocks.nether_brick, 0, 3);
		world.setBlock(x + 6, y + 5, z + 8, Blocks.nether_brick, 0, 3);
		world.setBlock(x + 6, y + 5, z + 7, Blocks.nether_brick, 0, 3);
		world.setBlock(x + 6, y + 5, z + 6, Blocks.nether_brick, 0, 3);
		world.setBlock(x + 6, y + 5, z + 5, Blocks.nether_brick, 0, 3);
		world.setBlock(x + 6, y + 5, z + 4, Blocks.nether_brick, 0, 3);
		world.setBlock(x + 6, y + 5, z + 3, Blocks.nether_brick, 0, 3);
		world.setBlock(x + 6, y + 5, z + 2, Blocks.nether_brick, 0, 3);
		world.setBlock(x + 6, y + 5, z + 1, Blocks.nether_brick_stairs, 2, 3);
		world.setBlock(x + 6, y + 5, z + 0, Blocks.air, 0, 3);
		world.setBlock(x + 7, y + 5, z + 11, Blocks.air, 0, 3);
		world.setBlock(x + 7, y + 5, z + 10, Blocks.nether_brick_stairs, 3, 3);
		world.setBlock(x + 7, y + 5, z + 9, Blocks.nether_brick, 0, 3);
		world.setBlock(x + 7, y + 5, z + 8, Blocks.nether_brick, 0, 3);
		world.setBlock(x + 7, y + 5, z + 7, Blocks.nether_brick, 0, 3);
		world.setBlock(x + 7, y + 5, z + 6, Blocks.nether_brick, 0, 3);
		world.setBlock(x + 7, y + 5, z + 5, Blocks.nether_brick, 0, 3);
		world.setBlock(x + 7, y + 5, z + 4, Blocks.nether_brick, 0, 3);
		world.setBlock(x + 7, y + 5, z + 3, Blocks.nether_brick, 0, 3);
		world.setBlock(x + 7, y + 5, z + 2, Blocks.nether_brick, 0, 3);
		world.setBlock(x + 7, y + 5, z + 1, Blocks.nether_brick_stairs, 2, 3);
		world.setBlock(x + 7, y + 5, z + 0, Blocks.air, 0, 3);
		world.setBlock(x + 8, y + 5, z + 11, Blocks.air, 0, 3);
		world.setBlock(x + 8, y + 5, z + 10, Blocks.nether_brick_stairs, 1, 3);
		world.setBlock(x + 8, y + 5, z + 9, Blocks.nether_brick_stairs, 1, 3);
		world.setBlock(x + 8, y + 5, z + 8, Blocks.nether_brick_stairs, 1, 3);
		world.setBlock(x + 8, y + 5, z + 7, Blocks.nether_brick_stairs, 1, 3);
		world.setBlock(x + 8, y + 5, z + 6, Blocks.nether_brick_stairs, 1, 3);
		world.setBlock(x + 8, y + 5, z + 5, Blocks.nether_brick_stairs, 1, 3);
		world.setBlock(x + 8, y + 5, z + 4, Blocks.nether_brick_stairs, 1, 3);
		world.setBlock(x + 8, y + 5, z + 3, Blocks.nether_brick_stairs, 1, 3);
		world.setBlock(x + 8, y + 5, z + 2, Blocks.nether_brick_stairs, 1, 3);
		world.setBlock(x + 8, y + 5, z + 1, Blocks.nether_brick_stairs, 2, 3);
		world.setBlock(x + 8, y + 5, z + 0, Blocks.air, 0, 3);
		world.setBlock(x + 9, y + 5, z + 11, Blocks.air, 0, 3);
		world.setBlock(x + 9, y + 5, z + 10, Blocks.air, 0, 3);
		world.setBlock(x + 9, y + 5, z + 9, Blocks.air, 0, 3);
		world.setBlock(x + 9, y + 5, z + 8, Blocks.air, 0, 3);
		world.setBlock(x + 9, y + 5, z + 7, Blocks.air, 0, 3);
		world.setBlock(x + 9, y + 5, z + 6, Blocks.air, 0, 3);
		world.setBlock(x + 9, y + 5, z + 5, Blocks.air, 0, 3);
		world.setBlock(x + 9, y + 5, z + 4, Blocks.air, 0, 3);
		world.setBlock(x + 9, y + 5, z + 3, Blocks.air, 0, 3);
		world.setBlock(x + 9, y + 5, z + 2, Blocks.air, 0, 3);
		world.setBlock(x + 9, y + 5, z + 1, Blocks.air, 0, 3);
		world.setBlock(x + 9, y + 5, z + 0, Blocks.air, 0, 3);

		
	
		
		int decorate = 1 + rand.nextInt(raidedChance);
		if (decorate == 4) {
			decorateEastFacingRaided(world, rand, x, y, z);
		} else {
			decorateEastFacing(world, rand, x, y, z);
		}
		
		return true;

	}
	
	public boolean decorateEastFacing(World world, Random rand, int x, int y, int z)
	{
		
		world.setBlock(x + 7, y + 1, z + 5, Blocks.chest, 0, 2);
		world.setBlock(x + 7, y + 1, z + 6, Blocks.chest, 0, 2);
		world.setBlock(x + 7, y + 1, z + 3, Blocks.furnace, 5, 5);
		world.setBlock(x + 7, y + 1, z + 8, OPWeapons.DemonFurnaceIdle, 4, 3);
		
		TileEntityChest Loot = new TileEntityChest();
		TileEntityChest Loot1 = new TileEntityChest();
		
		
		world.setTileEntity(x + 7, y + 1, z + 5, Loot);
		world.setTileEntity(x + 7, y + 1, z + 6, Loot1);
		

		world.setBlock(x+1, y + 1, z + 5, Blocks.wooden_door, 0 , 1);
		world.setBlock(x+1, y + 2, z + 5, Blocks.wooden_door, 8, 1);
		world.setBlock(x+1, y + 1, z + 6, Blocks.wooden_door, 0 , 1);
		world.setBlock(x+1, y + 2, z + 6, Blocks.wooden_door, 9 , 1);
		
		world.setBlock(x + 6, y + 1, z + 9, Blocks.bed, 3 ,0);
		world.setBlock(x + 7, y + 1, z + 9, Blocks.bed, 11 ,0);
		
		world.setBlock(x + 7, y + 1, z + 2, Blocks.anvil, 0, 3);
		world.setBlock(x + 7, y + 2, z + 10, Blocks.glass, 0, 3);
		world.setBlock(x + 7, y + 2, z + 4, Blocks.flower_pot, 1, 3);
		world.setBlock(x + 4, y + 4, z + 5, OPWeapons.demonLight, 0, 3);
		world.setBlock(x + 4, y + 5, z + 10, Blocks.nether_brick_stairs, 3, 3);
		world.setBlock(x + 4, y + 5, z + 9, Blocks.nether_brick, 0, 3);
		world.setBlock(x + 3, y + 5, z + 7, Blocks.nether_brick, 0, 3);
		world.setBlock(x + 5, y + 2, z + 10, Blocks.glass, 0, 3);
		world.setBlock(x + 0, y + 2, z + 7, Blocks.torch, 5, 3);
		world.setBlock(x + 0, y + 2, z + 4, Blocks.torch, 5, 3);
		
		lootTable(Loot, Loot1);
		
		
		
		return true;
	}
	
	public boolean decorateEastFacingRaided(World world, Random rand, int x, int y, int z)
	{
		
		world.setBlock(x + 7, y + 1, z + 5, Blocks.chest, 0, 2);
		world.setBlock(x + 7, y + 1, z + 6, Blocks.chest, 0, 2);
		world.setBlock(x + 7, y + 1, z + 3, Blocks.furnace, 5, 5);
		world.setBlock(x + 7, y + 1, z + 8, OPWeapons.DemonFurnaceIdle, 4, 3);
		
		TileEntityChest Loot = new TileEntityChest();
		TileEntityChest Loot1 = new TileEntityChest();
		
		
		world.setTileEntity(x + 7, y + 1, z + 5, Loot);
		world.setTileEntity(x + 7, y + 1, z + 6, Loot1);
		
		
		//world.setBlock(x+1, y + 1, z + 5, Blocks.wooden_door, 0 , 1);
		//world.setBlock(x+1, y + 2, z + 5, Blocks.wooden_door, 8, 1);
		world.setBlock(x+1, y + 1, z + 6, Blocks.wooden_door, 4 , 1);
		world.setBlock(x+1, y + 2, z + 6, Blocks.wooden_door, 9 , 1);
		
		// x=9, z= 1->10, y = 3->0
		
		
		for (int c = 3; c > -1; c--) {
			for (int k = 1; k < 11; k++) {
				world.setBlock(x+9, y+c, z+k, Blocks.vine,2,3);
			}		
		}
		
		
		
		
		//world.setBlock(x + 6, y + 1, z + 9, Blocks.bed, 3 ,0);
		//world.setBlock(x + 7, y + 1, z + 9, Blocks.bed, 11 ,0);
		world.setBlock(x + 7, y + 1, z + 2, Blocks.anvil, 10, 3);
		world.setBlock(x + 7, y + 2, z + 10, Blocks.web, 0, 3);
		world.setBlock(x + 4, y + 4, z + 5, Blocks.web, 0, 3);
		world.setBlock(x + 5, y + 2, z + 10, Blocks.web, 0, 3);
		
		lootTableRaided(Loot, Loot1);
		
		
		
		return true;
	}
	
	public boolean generate_northfacing(World world, Random rand, int x, int y, int z)
	{
